Workbook
Name Scenario: Cover!$C$6
Name Students_S: Assumptions!$G$6
Name Students_M: Assumptions!$G$7
Name Students_L: Assumptions!$G$8
Name Fee_S: Assumptions!$G$9
Name Fee_M: Assumptions!$G$10
Name Fee_L: Assumptions!$G$11
Name OnboardMult_S: Assumptions!$G$12
Name OnboardMult_M: Assumptions!$G$13
Name OnboardMult_L: Assumptions!$G$14
Name DropoutRate: Assumptions!$G$16
Name UpfrontShare: Assumptions!$G$17
Name NInstalments: Assumptions!$G$18
Name RefundEnforced: Assumptions!$G$19
Name CourseMonths: Assumptions!$G$20
Name BlindMonths: Assumptions!$G$21
Name Preventable: Assumptions!$G$22
Name MinorShare: Assumptions!$G$23
Name Recall_Minor: Assumptions!$G$24
Name Recall_Adult: Assumptions!$G$25
Name Precision: Assumptions!$G$26
Name ActionRate: Assumptions!$G$27
Name InterventionSuccess: Assumptions!$G$28
Name AdmissionUplift: Assumptions!$G$29
Name MarginExtraAdmission: Assumptions!$G$30
Name StaffHoursSaved: Assumptions!$G$31
Name StaffHourCost: Assumptions!$G$32
Name InterventionMinutes: Assumptions!$G$33
Name MentorHourCost: Assumptions!$G$34
Name GST: Assumptions!$G$35
Name ITCShare: Assumptions!$G$36
Name ListPrice: Assumptions!$G$38
Name CompetitorAnchor: Assumptions!$G$39
Name CompetitorAnchorHigh: Assumptions!$G$40
Name MinFee: Assumptions!$G$41
Name NegotiationDisc: Assumptions!$G$42
Name PrepayUptake: Assumptions!$G$43
Name PrepayDisc: Assumptions!$G$44
Name BadDebt: Assumptions!$G$45
Name GatewayFee: Assumptions!$G$46
Name ReportsPerStudentMonth: Assumptions!$G$48
Name TokensInPerReport: Assumptions!$G$49
Name TokensOutPerReport: Assumptions!$G$50
Name LLMPriceIn: Assumptions!$G$51
Name LLMPriceOut: Assumptions!$G$52
Name WAMsgsPerStudentMonth: Assumptions!$G$53
Name WAPricePerMsg: Assumptions!$G$54
Name ComputePerStudentMonth: Assumptions!$G$55
Name ConsentCostPerStudentYear: Assumptions!$G$56
Name ServerCostMonth: Assumptions!$G$57
Name BSPFeeMonth: Assumptions!$G$58
Name InstPerStack: Assumptions!$G$59
Name CompliancePerInstMonth: Assumptions!$G$60
Name CSM_CTC: Assumptions!$G$62
Name InstPerCSM: Assumptions!$G$63
Name RepCTC: Assumptions!$G$64
Name RepTravel: Assumptions!$G$65
Name SalesOverheadPct: Assumptions!$G$66
Name PilotsPerRepMonth: Assumptions!$G$67
Name PilotConv: Assumptions!$G$68

Sheet Cover
A1: The Data Moat — Financial Model
A2: Institute Intelligence Platform · Nextute × Finance Club IIT Patna, Case B · v1.1 CFO audit · 2026-10-22
B6: SCENARIO (1 = Bear, 2 = Base, 3 = Bull) → | C6: 2 | D6: =CHOOSE(Scenario,"Bear","Base","Bull")
B7: Model checks | C7: =IF(ErrorCount=0,"ALL CHECKS PASS","ERRORS: "&ErrorCount) | D7: ="Warnings to discuss: "&WarningCount
B9: Headline (Mid institute, 400 students, live scenario) | C9: Our model | D9: Guide (naive)
B10: Effective dropout reduction | C10: =Institute_ROI!E37 | D10: =G_Prevent
B11: Dropouts prevented per year | C11: =Institute_ROI!E38 | D11: =Institute_ROI!$E$67
B12: Institute ROI (all benefits) | C12: =Institute_ROI!E54 | D12: =Institute_ROI!$E$70
B13: Institute ROI (hard benefits: fees + staff time) | C13: =Institute_ROI!E56 | D13: =Institute_ROI!$E$70
B14: Institute ROI (fees only) | C14: =Institute_ROI!E55 | D14: =Institute_ROI!$E$70
B15: Break-even: students to save per year | C15: =Institute_ROI!E57 | D15: =Institute_ROI!$E$71
B16: Extra admissions needed to break even (after fees + staff time) | C16: =Institute_ROI!E60 | D16: n/a
B17: Platform cost as % of a student's fee | C17: =Institute_ROI!E62 | D17: =G_Price*G_Months/G_Fee
B18: Avg monthly revenue per institute | C18: =Unit_Econ!E33 | D18: =Unit_Econ!$I$5
B19: Contribution margin | C19: =Unit_Econ!E38 | D19: =Unit_Econ!$I$6/Unit_Econ!$I$5
B20: CAC: sales + marketing per paying institute | C20: =Unit_Econ!E43 | D20: =G_CAC
B21: Fully loaded acquisition cost | C21: =Unit_Econ!E44 | D21: =Unit_Econ!$I$7
B22: LTV (discounted) | C22: =Unit_Econ!E51 | D22: =Unit_Econ!$I$9
B23: LTV ÷ acquisition cost (discounted) | C23: =Unit_Econ!E52 | D23: =Unit_Econ!$I$10
B24: LTV ÷ acquisition cost (undiscounted, peer convention) | C24: =Unit_Econ!E56 | D24: =Unit_Econ!$I$10
B25: Payback, survival-weighted (months) | C25: =Unit_Econ!E53 | D25: =Unit_Econ!$I$8
B26: Payback, simple (months) | C26: =Unit_Econ!E54 | D26: =Unit_Econ!$I$8
B27: Institutes needed to cover fixed team cost (steady state) | C27: =Unit_Econ!I16 | D27: n/a
B28: 3-year: revenue in year 3 | C28: =Projection!$F$87 | D28: n/a
B29: 3-year: EBITDA in year 3 | C29: =Projection!$F$93 | D29: n/a
B30: 3-year: paying institutes at the end of year 3 | C30: =Projection!$F$96 | D30: n/a
B31: 3-year: funding the model says we need | C31: =Projection!$D$103 | D31: n/a
B32: 3-year: break-even month (3 positive months in a row) | C32: =Projection!$D$105 | D32: n/a
B34: Colour code
B35: Blue text | C35: Input — edit only these (Assumptions D:F and N, Seasonality, grid points, Scenario)
B36: Black text | C36: Formula
B37: Green text | C37: Link from another sheet
B38: Yellow fill | C38: Key lever / live value
B39: Green fill | C39: Key output
B41: How to use
B42: 1 | C42: Pick a scenario in C6. Bear / Base / Bull flex only the scenario drivers (Assumptions column N).
B43: 2 | C43: Change an input on Assumptions (Bear/Base/Bull) — never type over a formula.
B44: 3 | C44: Cover C7 must say ALL CHECKS PASS before you quote any number.
B45: 4 | C45: To rebuild from the CSVs: python build_model.py (Financial_Model folder).
B47: Evidence labels | C47: Researched/Public = sourced (see Sources) · Guide = case brief · Assumption = unverified · Structural = modelling convention
...

Sheet Assumptions
A1: Assumptions — every input in the model lives here
A2: Blue = input you may edit (Bear / Base / Bull). LIVE = the value the model uses: rows marked Y in 'Scenario driver' follow the Cover switch, CHOOSE(Scenario, Bear, Base, Bull); rows marked N always use Base. Bear = worse for OUR business. Type: Researched/Public = sourced · Guide = case brief · Assumption = unverified · Structural = convention.
A4: Name (named range → Live) | B4: Input | C4: Unit | D4: Bear | E4: Base | F4: Bull | G4: LIVE | H4: Type | I4: Confidence | J4: Source | K4: Note | L4: Pct out of [0,1] | M4: Live outside Bear–Bull | N4: Scenario driver (Y/N)
A5: Segments
A6: Students_S | B6: Students per institute - Small | C6: students | D6: 180 | E6: 180 | F6: 180 | G6: =IF(N6="Y",CHOOSE(Scenario,D6,E6,F6),E6) | H6: Assumption | I6: M | J6: Case brief range 150-2000; our cut <250 | K6: Segment midpoint | L6: 0 | M6: =IF(AND(G6>=MIN(D6,F6),G6<=MAX(D6,F6)),0,1) | N6: N
A7: Students_M | B7: Students per institute - Mid | C7: students | D7: 400 | E7: 400 | F7: 400 | G7: =IF(N7="Y",CHOOSE(Scenario,D7,E7,F7),E7) | H7: Guide | I7: M | J7: Case brief baseline 400 | L7: 0 | M7: =IF(AND(G7>=MIN(D7,F7),G7<=MAX(D7,F7)),0,1) | N7: N
A8: Students_L | B8: Students per institute - Large | C8: students | D8: 1200 | E8: 1200 | F8: 1200 | G8: =IF(N8="Y",CHOOSE(Scenario,D8,E8,F8),E8) | H8: Assumption | I8: M | J8: Case brief range 150-2000; our cut >800 | L8: 0 | M8: =IF(AND(G8>=MIN(D8,F8),G8<=MAX(D8,F8)),0,1) | N8: N
A9: Fee_S | B9: Annual fee per student - Small | C9: Rs/yr | D9: 50000 | E9: 60000 | F9: 75000 | G9: =IF(N9="Y",CHOOSE(Scenario,D9,E9,F9),E9) | H9: Researched | I9: L | J9: R2 local-institute evidence: Vedantu Gaya Rs50-56k, Rupantri Muzaffarpur Rs55-60k, GOAL Patna Rs51-99k; PS baseline Rs60k | K9: Audit 2026-10-22: re-based to local evidence (was Rs65k Base) | L9: 0 | M9: =IF(AND(G9>=MIN(D9,F9),G9<=MAX(D9,F9)),0,1) | N9: N
A10: Fee_M | B10: Annual fee per student - Mid | C10: Rs/yr | D10: 60000 | E10: 75000 | F10: 95000 | G10: =IF(N10="Y",CHOOSE(Scenario,D10,E10,F10),E10) | H10: Researched | I10: L | J10: R2: PS baseline Rs60k = Bear; local Tier-2 evidence Rs50k-1.2L (Patna independents); chain fees (Vedantu Patna Rs95k) = Bull | K10: Audit 2026-10-22: was Rs95k Base (chain pricing); our customers are local independents | L10: 0 | M10: =IF(AND(G10>=MIN(D10,F10),G10<=MAX(D10,F10)),0,1) | N10: N
A11: Fee_L | B11: Annual fee per student - Large | C11: Rs/yr | D11: 85000 | E11: 100000 | F11: 125000 | G11: =IF(N11="Y",CHOOSE(Scenario,D11,E11,F11),E11) | H11: Researched | I11: M | J11: R2: Udaan Patna Rs1.15-1.25L/yr (own site, 2025-27); chains Rs1.1-1.4L (Motion, Allen Indore, Vedantu Lucknow) | K11: Audit 2026-10-22: was Rs125k Base | L11: 0 | M11: =IF(AND(G11>=MIN(D11,F11),G11<=MAX(D11,F11)),0,1) | N11: N
A12: OnboardMult_S | B12: Onboarding cost multiplier - Small | C12: x | D12: 0.8 | E12: 0.8 | F12: 0.8 | G12: =IF(N12="Y",CHOOSE(Scenario,D12,E12,F12),E12) | H12: Assumption | I12: L | J12: Fewer batches to migrate | L12: 0 | M12: =IF(AND(G12>=MIN(D12,F12),G12<=MAX(D12,F12)),0,1) | N12: N
A13: OnboardMult_M | B13: Onboarding cost multiplier - Mid | C13: x | D13: 1 | E13: 1 | F13: 1 | G13: =IF(N13="Y",CHOOSE(Scenario,D13,E13,F13),E13) | H13: Structural | I13: H | J13: Reference segment | L13: 0 | M13: =IF(AND(G13>=MIN(D13,F13),G13<=MAX(D13,F13)),0,1) | N13: N
A14: OnboardMult_L | B14: Onboarding cost multiplier - Large | C14: x | D14: 1.6 | E14: 1.6 | F14: 1.6 | G14: =IF(N14="Y",CHOOSE(Scenario,D14,E14,F14),E14) | H14: Assumption | I14: L | J14: More batches and staff to train | L14: 0 | M14: =IF(AND(G14>=MIN(D14,F14),G14<=MAX(D14,F14)),0,1) | N14: N
A15: Institute
A16: DropoutRate | B16: Mid-session dropout/default rate | C16: % of students/yr | D16: 0.08 | E16: 0.12 | F16: 0.18 | G16: =IF(N16="Y",CHOOSE(Scenario,D16,E16,F16),E16) | H16: Researched | I16: L | J16: PS Section 7 baseline 8-15% (12% used); CFI 'at least 10 per cent of students in every batch' (ThePrint 2025) is a floor; tech generator uses 18% (knob 12-25%) | K16: Audit 2026-10-22: Base back to the PS's 12% (was 10%). Tech's 18% is a stress calibration that gives enough validation events | L16: =IF(OR(G16<0,G16>1),1,0) | M16: =IF(AND(G16>=MIN(D16,F16),G16<=MAX(D16,F16)),0,1) | N16: Y
A17: UpfrontShare | B17: Share of students paying full fee upfront | C17: % | D17: 0.4 | E17: 0.25 | F17: 0.15 | G17: =IF(N17="Y",CHOOSE(Scenario,D17,E17,F17),E17) | H17: Assumption | I17: L | J17: R2: not found. Instalments are the norm (Allen 2; PW 3; Aakash several; Rajasthan Act s.6(2)(d) >=4 option) | K17: TECH_PLAN's 35% had no source | L17: =IF(OR(G17<0,G17>1),1,0) | M17: =IF(AND(G17>=MIN(D17,F17),G17<=MAX(D17,F17)),0,1) | N17: N
A18: NInstalments | B18: Instalments per year for non-upfront payers | C18: count | D18: 2 | E18: 3 | F18: 4 | G18: =IF(N18="Y",CHOOSE(Scenario,D18,E18,F18),E18) | H18: Researched | I18: M | J18: R2: Allen 2 (2nd within 45 days); PW 3; Rajasthan Act 16/2025 s.6(2)(d) min. 4 equal | K18: Fewer instalments = cash collected early = less at risk | L18: 0 | M18: =IF(AND(G18>=MIN(D18,F18),G18<=MAX(D18,F18)),0,1) | N18: N
A19: RefundEnforced | B19: Share of upfront leavers actually refunded pro-rata | C19: % | D19: 0.1 | E19: 0.3 | F19: 0.6 | G19: =IF(N19="Y",CHOOSE(Scenario,D19,E19,F19),E19) | H19: Assumption | I19: L | J19: R2: MoE Guidelines 2024 cl.8(iv) and Rajasthan s.13(4) require pro-rata refund within 10 days; MoE is advisory and Allen/Aakash/PW practice is cut-off or no refund | K19: Refunded upfront leavers = fee at risk | L19: =IF(OR(G19<0,G19>1),1,0) | M19: =IF(AND(G19>=MIN(D19,F19),G19<=MAX(D19,F19)),0,1) | N19: N
A20: CourseMonths | B20: Course length | C20: months | D20: 10 | E20: 10 | F20: 10 | G20: =IF(N20="Y",CHOOSE(Scenario,D20,E20,F20),E20) | H20: Guide | I20: H | J20: Case brief ~10 months | L20: 0 | M20: =IF(AND(G20>=MIN(D20,F20),G20<=MAX(D20,F20)),0,1) | N20: N
A21: BlindMonths | B21: Months before the model can flag (no test data yet) | C21: months | D21: 3 | E21: 2 | F21: 1 | G21: =IF(N21="Y",CHOOSE(Scenario,D21,E21,F21),E21) | H21: Assumption | I21: M | J21: The model needs 1-2 cumulative tests before it can flag (tech generator: a full mock every 14 days) | K21: Audit: Base 2 (was 1). Dropouts in these months cannot be caught | L21: 0 | M21: =IF(AND(G21>=MIN(D21,F21),G21<=MAX(D21,F21)),0,1) | N21: N
A22: Preventable | B22: Share of dropouts that are preventable (check only) | C22: % | D22: 0.35 | E22: 0.55 | F22: 0.65 | G22: =IF(N22="Y",CHOOSE(Scenario,D22,E22,F22),E22) | H22: Assumption | I22: L | J22: Tech generator reasons_mix: academic gap 35% + financial 20% are addressable; relocation 20%, switched institute 15%, health 10% are not | K22: Audit: aligned with the tech team; used only as a sanity check on the trial effect | L22: =IF(OR(G22<0,G22>1),1,0) | M22: =IF(AND(G22>=MIN(D22,F22),G22<=MAX(D22,F22)),0,1) | N22: N
A23: MinorShare | B23: Share of students under 18 | C23: % | D23: 0.85 | E23: 0.78 | F23: 0.65 | G23: =IF(N23="Y",CHOOSE(Scenario,D23,E23,F23),E23) | H23: Public | I23: M | J23: Tech generator: 78% of students are minors at join (FEASIBILITY_CHECK s.6); JEE/NEET Class 11-12 are 16-17 | K23: Audit: aligned with the tech team's synthetic data | L23: =IF(OR(G23<0,G23>1),1,0) | M23: =IF(AND(G23>=MIN(D23,F23),G23<=MAX(D23,F23)),0,1) | N23: N
A24: Recall_Minor | B24: Model recall on minors (academic-support + rules) | C24: % | D24: 0.25 | E24: 0.32 | F24: 0.45 | G24: =IF(N24="Y",CHOOSE(Scenario,D24,E24,F24),E24) | H24: Assumption | I24: M | J24: Tech FEASIBILITY_CHECK s.2 and s.6: recall 0.31 on the actual generator; 0.49-0.55 of gradual dropouts x 75% gradual = 0.37-0.41 of all dropouts; minors get the academic-support model + rules only. Replace with metrics.json | K24: Audit 2026-10-22: was 0.55 Base (above anything the tech team measured). 25% of dropouts are sudden and unpredictable | L24: =IF(OR(G24<0,G24>1),1,0) | M24: =IF(AND(G24>=MIN(D24,F24),G24<=MAX(D24,F24)),0,1) | N24: Y
A25: Recall_Adult | B25: Model recall on 18+ (full ML) | C25: % | D25: 0.3 | E25: 0.42 | F25: 0.6 | G25: =IF(N25="Y",CHOOSE(Scenario,D25,E25,F25),E25) | H25: Assumption | I25: M | J25: Tech FEASIBILITY_CHECK s.2: 0.37-0.41 of all dropouts at fixed workload; adults (18+) can use full ML incl. engagement. Replace with metrics.json | K25: Audit 2026-10-22: was 0.65 Base. OULAD AUC 0.706-0.794 (public) is ranking quality, not recall at a workload | L25: =IF(OR(G25<0,G25>1),1,0) | M25: =IF(AND(G25>=MIN(D25,F25),G25<=MAX(D25,F25)),0,1) | N25: Y
A26: Precision | B26: Precision of at-risk flag | C26: % | D26: 0.1 | E26: 0.15 | F26: 0.25 | G26: =IF(N26="Y",CHOOSE(Scenario,D26,E26,F26),E26) | H26: Researched | I26: M | J26: Tech FEASIBILITY_CHECK s.6: precision@top-4%/wk 0.136; with 38% of students flagged at least once and recall 0.31, student-level precision is about 0.15 (derived) | K26: Audit 2026-10-22: was 0.35. Low precision means most mentor calls go to students who would not have left | L26: =IF(OR(G26<0,G26>1),1,0) | M26: =IF(AND(G26>=MIN(D26,F26),G26<=MAX(D26,F26)),0,1) | N26: Y
A27: ActionRate | B27: Share of flags the institute assigns to outreach | C27: % | D27: 0.7 | E27: 0.9 | F27: 1 | G27: =IF(N27="Y",CHOOSE(Scenario,D27,E27,F27),E27) | H27: Assumption | I27: L | J27: Mentor capacity; the RCT effect below is already intention-to-treat | K27: Primary research needed | L27: =IF(OR(G27<0,G27>1),1,0) | M27: =IF(AND(G27>=MIN(D27,F27),G27<=MAX(D27,F27)),0,1) | N27: N
A28: InterventionSuccess | B28: Dropout reduction among flagged students given outreach (RCT) | C28: relative % | D28: 0.05 | E28: 0.15 | F28: 0.3 | G28: =IF(N28="Y",CHOOSE(Scenario,D28,E28,F28),E28) | H28: Researched | I28: M | J28: R4: mean 15.8% / median 12.5% over 8 RCTs - OU outreach RCT 2020 -19%/-35%; Room to Read India -30%; Bergman parent texts; MAAPS/Samata/Oreopoulos nulls (research/R4_R5) | K28: Borrowed from other settings - not our measured effect | L28: =IF(OR(G28<0,G28>1),1,0) | M28: =IF(AND(G28>=MIN(D28,F28),G28<=MAX(D28,F28)),0,1) | N28: Y
A29: AdmissionUplift | B29: Admissions uplift next session from results/parent trust | C29: % of students | D29: 0 | E29: 0.01 | F29: 0.03 | G29: =IF(N29="Y",CHOOSE(Scenario,D29,E29,F29),E29) | H29: Assumption | I29: L | J29: No evidence - Bear = 0 | L29: =IF(OR(G29<0,G29>1),1,0) | M29: =IF(AND(G29>=MIN(D29,F29),G29<=MAX(D29,F29)),0,1) | N29: Y
A30: MarginExtraAdmission | B30: Institute margin on one extra admission | C30: % | D30: 0.4 | E30: 0.6 | F30: 0.8 | G30: =IF(N30="Y",CHOOSE(Scenario,D30,E30,F30),E30) | H30: Assumption | I30: L | J30: Marginal seat in an existing batch | L30: =IF(OR(G30<0,G30>1),1,0) | M30: =IF(AND(G30>=MIN(D30,F30),G30<=MAX(D30,F30)),0,1) | N30: N
A31: StaffHoursSaved | B31: Staff hours saved per month | C31: hours/month | D31: 10 | E31: 25 | F31: 50 | G31: =IF(N31="Y",CHOOSE(Scenario,D31,E31,F31),E31) | H31: Guide | I31: L | J31: Case brief value lever; primary research needed | L31: 0 | M31: =IF(AND(G31>=MIN(D31,F31),G31<=MAX(D31,F31)),0,1) | N31: N
A32: StaffHourCost | B32: Cost of one admin staff hour | C32: Rs/hour | D32: 75 | E32: 100 | F32: 150 | G32: =IF(N32="Y",CHOOSE(Scenario,D32,E32,F32),E32) | H32: Researched | I32: M | J32: R5: Tier-2 executive pay Rs18-25k/month (Payscale/Indeed Patna) / ~200 h | L32: 0 | M32: =IF(AND(G32>=MIN(D32,F32),G32<=MAX(D32,F32)),0,1) | N32: N
A33: InterventionMinutes | B33: Mentor minutes per intervention | C33: minutes | D33: 240 | E33: 120 | F33: 60 | G33: =IF(N33="Y",CHOOSE(Scenario,D33,E33,F33),E33) | H33: Assumption | I33: L | J33: Assumption: the trials behind the 15% effect used multi-touch outreach (call + parent meeting + follow-ups), about 2 hours per flagged student | K33: Audit 2026-10-22: was 30 minutes Base, too thin to deliver the trial effect | L33: 0 | M33: =IF(AND(G33>=MIN(D33,F33),G33<=MAX(D33,F33)),0,1) | N33: N
A34: MentorHourCost | B34: Cost of one mentor hour | C34: Rs/hour | D34: 250 | E34: 200 | F34: 150 | G34: =IF(N34="Y",CHOOSE(Scenario,D34,E34,F34),E34) | H34: Assumption | I34: M | J34: Teacher pay ~Rs30-50k/month / ~200 h | L34: 0 | M34: =IF(AND(G34>=MIN(D34,F34),G34<=MAX(D34,F34)),0,1) | N34: N
A35: GST | B35: GST on SaaS | C35: % | D35: 0.18 | E35: 0.18 | F35: 0.18 | G35: =IF(N35="Y",CHOOSE(Scenario,D35,E35,F35),E35) | H35: Researched | I35: M | J35: R6: 18% (heading 9983 residual entry; Notif. 11/2017-CTR as amended by 15/2025-CTR) | K35: SAC code 9983 vs 9984 unconfirmed - ask a CA | L35: =IF(OR(G35<0,G35>1),1,0) | M35: =IF(AND(G35>=MIN(D35,F35),G35<=MAX(D35,F35)),0,1) | N35: N
A36: ITCShare | B36: Share of institutes that reclaim our GST as input credit | C36: % | D36: 0.3 | E36: 0.6 | F36: 0.9 | G36: =IF(N36="Y",CHOOSE(Scenario,D36,E36,F36),E36) | H36: Assumption | I36: L | J36: R6: coaching is taxable at 18%; registration mandatory above Rs20L turnover; CGST s.16(1) gives ITC to registered persons. A 180-student institute turns over ~Rs1 Cr, so legally registered - but cash/informal practice in Tier-3 | K36: Was 'all unregistered' in the naive view | L36: =IF(OR(G36<0,G36>1),1,0) | M36: =IF(AND(G36>=MIN(D36,F36),G36<=MAX(D36,F36)),0,1) | N36: N
A37: Pricing
A38: ListPrice | B38: List price per active student per month | C38: Rs/student/month | D38: 20 | E38: 30 | F38: 40 | G38: =IF(N38="Y",CHOOSE(Scenario,D38,E38,F38),E38) | H38: Assumption | I38: L | J38: R1: ERP/LMS anchors Rs4-21/student/month at 400 students (Classplus/Fedena/Graphy); no competitor bundles OMR + topic analytics + Hindi WhatsApp | K38: Decision lever - test in interviews (Van Westendorp) | L38: 0 | M38: =IF(AND(G38>=MIN(D38,F38),G38<=MAX(D38,F38)),0,1) | N38: Y
A39: CompetitorAnchor | B39: What institutes already pay for an ERP/LMS | C39: Rs/student/month | D39: 4.17 | E39: 10.42 | F39: 20.83 | G39: =IF(N39="Y",CHOOSE(Scenario,D39,E39,F39),E39) | H39: Researched | I39: M | J39: R1: Classplus Starter Rs19999/yr (Capterra); Fedena Standard / Graphy Grow Rs50k/yr; Fedena Ultimate Rs1L/yr - all at 400 students | K39: Reference only - not used in revenue | L39: 0 | M39: =IF(AND(G39>=MIN(D39,F39),G39<=MAX(D39,F39)),0,1) | N39: N
A40: CompetitorAnchorHigh | B40: Highest priced ERP/LMS anchor found | C40: Rs/student/month | D40: 20.83 | E40: 20.83 | F40: 20.83 | G40: =IF(N40="Y",CHOOSE(Scenario,D40,E40,F40),E40) | H40: Researched | I40: M | J40: R1: Fedena Ultimate / Graphy Rise Rs1L/yr at 400 students | K40: Used in a warning check | L40: 0 | M40: =IF(AND(G40>=MIN(D40,F40),G40<=MAX(D40,F40)),0,1) | N40: N
A41: MinFee | B41: Minimum monthly fee per institute | C41: Rs/month | D41: 2000 | E41: 3000 | F41: 4000 | G41: =IF(N41="Y",CHOOSE(Scenario,D41,E41,F41),E41) | H41: Assumption | I41: L | J41: FINANCE_PLAN s.3.2 | L41: 0 | M41: =IF(AND(G41>=MIN(D41,F41),G41<=MAX(D41,F41)),0,1) | N41: N
...

Sheet Seasonality
A1: Seasonality, dropout timing and the 60-month timeline
A2: Session month 1 = April. Blue cells are inputs (currently assumptions, see Source).
A3: A. Active-student index and renewal (churn) months
A4: No. | B4: Month | C4: Active-student index | D4: Renewal month (1/0) | E4: Sales intensity index | F4: Source
A5: 1 | B5: Apr | C5: 0.85 | D5: 1 | E5: 1.6 | F5: Assumption (L): new session starts; admissions still coming in | flag: Assumption: renewal decision for the new session | sales index: Assumption: PS Section 7 'sales cycle peaks before the new session (March-June)'; mean 1.0
A6: 2 | B6: May | C6: 0.95 | D6: 1 | E6: 2 | F6: Assumption (L) | flag: Assumption
A7: 3 | B7: Jun | C7: 1 | D7: 0 | E7: 1.7 | F7: Assumption (L)
A8: 4 | B8: Jul | C8: 1 | D8: 0 | E8: 1 | F8: Assumption (L)
A9: 5 | B9: Aug | C9: 1 | D9: 0 | E9: 0.7 | F9: Assumption (L)
A10: 6 | B10: Sep | C10: 1 | D10: 0 | E10: 0.6 | F10: Assumption (L)
A11: 7 | B11: Oct | C11: 0.98 | D11: 0 | E11: 0.5 | F11: Assumption (L): dropouts start reducing roster
A12: 8 | B12: Nov | C12: 0.96 | D12: 0 | E12: 0.5 | F12: Assumption (L)
A13: 9 | B13: Dec | C13: 0.93 | D13: 0 | E13: 0.4 | F13: Assumption (L)
A14: 10 | B14: Jan | C14: 0.85 | D14: 0 | E14: 0.5 | F14: Assumption (L): JEE Main Jan; 12th students thin out
A15: 11 | B15: Feb | C15: 0.6 | D15: 0 | E15: 0.8 | F15: Assumption (L): board exams
A16: 12 | B16: Mar | C16: 0.45 | D16: 1 | E16: 1.7 | F16: Assumption (L): boards end; session over for 12th | flag: Assumption: post-exam churn window
B18: Renewal months per year | C18: =SUM(Season_Flag)
A20: B. When in the course students drop out
A21: Course month | C21: Share of dropouts | D21: Share of course left | E21: Source
A22: 1 | B22: Course month 1 | C22: 0.03 | D22: =MAX(0,(CourseMonths-A22)/CourseMonths) | E22: Assumption (L): PS Section 7 'highest in first 4-5 months'; tech generator peak months 3-4 (43% of dropouts there, FEASIBILITY_CHECK s.6). Audit 2026-10-22: was front-loaded (30% in months 1-2)
A23: 2 | B23: Course month 2 | C23: 0.1 | D23: =MAX(0,(CourseMonths-A23)/CourseMonths) | E23: Assumption (L): same curve
A24: 3 | B24: Course month 3 | C24: 0.2 | D24: =MAX(0,(CourseMonths-A24)/CourseMonths) | E24: Assumption (L): same curve
A25: 4 | B25: Course month 4 | C25: 0.23 | D25: =MAX(0,(CourseMonths-A25)/CourseMonths) | E25: Assumption (L): same curve
A26: 5 | B26: Course month 5 | C26: 0.15 | D26: =MAX(0,(CourseMonths-A26)/CourseMonths) | E26: Assumption (L): same curve
A27: 6 | B27: Course month 6 | C27: 0.09 | D27: =MAX(0,(CourseMonths-A27)/CourseMonths) | E27: Assumption (L): same curve
A28: 7 | B28: Course month 7 | C28: 0.07 | D28: =MAX(0,(CourseMonths-A28)/CourseMonths) | E28: Assumption (L): same curve
A29: 8 | B29: Course month 8 | C29: 0.05 | D29: =MAX(0,(CourseMonths-A29)/CourseMonths) | E29: Assumption (L): same curve
A30: 9 | B30: Course month 9 | C30: 0.04 | D30: =MAX(0,(CourseMonths-A30)/CourseMonths) | E30: Assumption (L): same curve
A31: 10 | B31: Course month 10 | C31: 0.04 | D31: =MAX(0,(CourseMonths-A31)/CourseMonths) | E31: Assumption (L): same curve
B32: Total (must be 100%) | C32: =SUM(DropTiming)
A34: C. Timeline for LTV: paid month t → calendar month, student index, renewal flag, discount factor
A36: t (paid month) | B36: Calendar month # | C36: Active-student index | D36: Renewal flag | E36: Discount factor
A37: 1 | B37: =MOD(StartMonth+A37-2,12)+1 | C37: =INDEX(Season_Idx,B37) | D37: =INDEX(Season_Flag,B37) | E37: =1/(1+DiscountRate)^(A37/12)
A38: 2 | B38: =MOD(StartMonth+A38-2,12)+1 | C38: =INDEX(Season_Idx,B38) | D38: =INDEX(Season_Flag,B38) | E38: =1/(1+DiscountRate)^(A38/12)
A39: 3 | B39: =MOD(StartMonth+A39-2,12)+1 | C39: =INDEX(Season_Idx,B39) | D39: =INDEX(Season_Flag,B39) | E39: =1/(1+DiscountRate)^(A39/12)
A40: 4 | B40: =MOD(StartMonth+A40-2,12)+1 | C40: =INDEX(Season_Idx,B40) | D40: =INDEX(Season_Flag,B40) | E40: =1/(1+DiscountRate)^(A40/12)
A41: 5 | B41: =MOD(StartMonth+A41-2,12)+1 | C41: =INDEX(Season_Idx,B41) | D41: =INDEX(Season_Flag,B41) | E41: =1/(1+DiscountRate)^(A41/12)
A42: 6 | B42: =MOD(StartMonth+A42-2,12)+1 | C42: =INDEX(Season_Idx,B42) | D42: =INDEX(Season_Flag,B42) | E42: =1/(1+DiscountRate)^(A42/12)
A43: 7 | B43: =MOD(StartMonth+A43-2,12)+1 | C43: =INDEX(Season_Idx,B43) | D43: =INDEX(Season_Flag,B43) | E43: =1/(1+DiscountRate)^(A43/12)
A44: 8 | B44: =MOD(StartMonth+A44-2,12)+1 | C44: =INDEX(Season_Idx,B44) | D44: =INDEX(Season_Flag,B44) | E44: =1/(1+DiscountRate)^(A44/12)
...

Sheet Pricing
A1: Pricing — list price, discounts, realised price
A2: Green = linked input · black = formula · green fill = output used elsewhere
B4: Item | C4: Unit | D4: LIVE
B5: Inputs (from Assumptions)
B6: List price per active student per month | C6: Rs/student/month | D6: =ListPrice
B7: Minimum monthly fee per institute | C7: Rs/month | D7: =MinFee
B8: Average negotiated discount off list | C8: % | D8: =NegotiationDisc
B9: Share of institutes choosing annual prepay | C9: % | D9: =PrepayUptake
B10: Annual prepay discount | C10: % | D10: =PrepayDisc
B11: GST on SaaS | C11: % | D11: =GST
B12: Realised price
B13: Effective discount = negotiation + prepay uptake × prepay discount | C13: % | D13: =D8+D9*D10
B14: Realised price per student-month (ex-GST) | C14: ₹/student/month | D14: =D6*(1-D13)
B15: Price the owner feels (incl. GST) | C15: ₹/student/month | D15: =D14*(1+D11)
B16: What institutes already pay for an ERP/LMS | C16: Rs/student/month | D16: =CompetitorAnchor
B17: Our realised price ÷ what institutes already pay for an ERP/LMS | C17: x | D17: =IF(D16>0,D14/D16,0)
A20: Packaging (for the deck; Pro price is the model's list price)
A21: Tier | B21: Contents | C21: Price | D21: Role
A22: Starter | B22: CSV / OMR upload, test-level reports, 1 batch | C22: 0 | D22: Free — lead generation, data on-ramp
A23: Pro (core) | B23: Topic heatmap, at-risk list with reasons, template parent reports | C23: =ListPrice | D23: Core paid plan, ₹/active student/month, min fee applies
A24: Premium (AI) | B24: GenAI Hindi/English parent reports on WhatsApp, percentile band, study plans | C24: Pro + add-on | D24: Upsell — NOT in base revenue until priced by research
A25: Annual plan | B25: Pro billed yearly upfront | C25: =ListPrice*(1-PrepayDisc) | D25: Cash up front, lower churn at renewal

Sheet COGS_Build
A1: COGS build-up — cost to serve one student (must match TECH_PLAN §16 / NB09)
A2: Mid-segment size used for the all-in figure. Tech plan target band: ₹3–10 per student-month.
B4: Item | C4: Unit | D4: LIVE
B5: Inputs (from Assumptions)
B6: AI parent reports per student per month | C6: reports | D6: =ReportsPerStudentMonth
B7: LLM input tokens per report | C7: tokens | D7: =TokensInPerReport
B8: LLM output tokens per report | C8: tokens | D8: =TokensOutPerReport
B9: LLM input price (hosted) | C9: Rs per 1M tokens | D9: =LLMPriceIn
B10: LLM output price (hosted) | C10: Rs per 1M tokens | D10: =LLMPriceOut
B11: WhatsApp utility messages per student per month | C11: messages | D11: =WAMsgsPerStudentMonth
B12: WhatsApp utility message price (India) | C12: Rs/message | D12: =WAPricePerMsg
B13: Compute + storage + backups per student | C13: Rs/student/month | D13: =ComputePerStudentMonth
B14: Consent OTP + verification per student | C14: Rs/student/yr | D14: =ConsentCostPerStudentYear
B15: App server + managed Postgres + backups per stack | C15: Rs/month | D15: =ServerCostMonth
B16: WhatsApp BSP platform fee per stack | C16: Rs/month | D16: =BSPFeeMonth
B17: Institutes sharing one server stack | C17: institutes | D17: =InstPerStack
B18: DPDP compliance cost per institute | C18: Rs/month | D18: =CompliancePerInstMonth
B19: Students per institute | C19: students | D19: =Students_M
B20: Variable cost per active student per month
B21: LLM (AI parent reports, hosted model) | C21: ₹/student/month | D21: =D6*(D7*D9+D8*D10)/1000000
B22: WhatsApp utility messages | C22: ₹/student/month | D22: =D11*D12
B23: Compute + storage + backups | C23: ₹/student/month | D23: =D13
B24: Consent OTP / verification (annual ÷ 12) | C24: ₹/student/month | D24: =D14/12
B25: Total variable COGS per student-month | C25: ₹/student/month | D25: =SUM(D21:D24)
B26: Fixed cost per institute per month
B27: Hosting share = (server + DB + WhatsApp BSP fee) ÷ institutes per stack | C27: ₹/institute/month | D27: =(D15+D16)/D17
B28: Hosting share + DPDP compliance | C28: ₹/institute/month | D28: =D27+D18
B29: All-in COGS per student-month at this size | C29: ₹/student/month | D29: =D25+D28/D19

Sheet Institute_ROI
A1: Institute ROI — does it pay for the owner? (per segment, live scenario)
A2: Same price and same dropout funnel as Unit_Econ. Green fill = key outputs.
B4: Line | C4: Unit | D4: Small (<250) | E4: Mid (250-800) | F4: Large (>800)
B5: Inputs (from Assumptions / Pricing)
B6: Students per institute | C6: students | D6: =Students_S | E6: =Students_M | F6: =Students_L
B7: Annual fee per student | C7: Rs/yr | D7: =Fee_S | E7: =Fee_M | F7: =Fee_L
B8: Mid-session dropout/default rate | C8: % of students/yr | D8: =DropoutRate | E8: =DropoutRate | F8: =DropoutRate
B9: Share of students paying full fee upfront | C9: % | D9: =UpfrontShare | E9: =UpfrontShare | F9: =UpfrontShare
B10: Instalments per year for non-upfront payers | C10: count | D10: =NInstalments | E10: =NInstalments | F10: =NInstalments
B11: Share of upfront leavers actually refunded pro-rata | C11: % | D11: =RefundEnforced | E11: =RefundEnforced | F11: =RefundEnforced
B12: Months before the model can flag (no test data yet) | C12: months | D12: =BlindMonths | E12: =BlindMonths | F12: =BlindMonths
B13: Share of students under 18 | C13: % | D13: =MinorShare | E13: =MinorShare | F13: =MinorShare
B14: Model recall on minors (academic-support + rules) | C14: % | D14: =Recall_Minor | E14: =Recall_Minor | F14: =Recall_Minor
B15: Model recall on 18+ (full ML) | C15: % | D15: =Recall_Adult | E15: =Recall_Adult | F15: =Recall_Adult
B16: Precision of at-risk flag | C16: % | D16: =Precision | E16: =Precision | F16: =Precision
B17: Share of flags the institute assigns to outreach | C17: % | D17: =ActionRate | E17: =ActionRate | F17: =ActionRate
B18: Dropout reduction among flagged students given outreach (RCT) | C18: relative % | D18: =InterventionSuccess | E18: =InterventionSuccess | F18: =InterventionSuccess
B19: Admissions uplift next session from results/parent trust | C19: % of students | D19: =AdmissionUplift | E19: =AdmissionUplift | F19: =AdmissionUplift
B20: Institute margin on one extra admission | C20: % | D20: =MarginExtraAdmission | E20: =MarginExtraAdmission | F20: =MarginExtraAdmission
B21: Staff hours saved per month | C21: hours/month | D21: =StaffHoursSaved | E21: =StaffHoursSaved | F21: =StaffHoursSaved
B22: Cost of one admin staff hour | C22: Rs/hour | D22: =StaffHourCost | E22: =StaffHourCost | F22: =StaffHourCost
B23: Mentor minutes per intervention | C23: minutes | D23: =InterventionMinutes | E23: =InterventionMinutes | F23: =InterventionMinutes
B24: Cost of one mentor hour | C24: Rs/hour | D24: =MentorHourCost | E24: =MentorHourCost | F24: =MentorHourCost
B25: List price per active student per month | C25: Rs/student/month | D25: =ListPrice | E25: =ListPrice | F25: =ListPrice
B26: Minimum monthly fee per institute | C26: Rs/month | D26: =MinFee | E26: =MinFee | F26: =MinFee
B27: GST on SaaS | C27: % | D27: =GST | E27: =GST | F27: =GST
B28: Share of institutes that reclaim our GST as input credit | C28: % | D28: =ITCShare | E28: =ITCShare | F28: =ITCShare
B29: Effective discount (Pricing) | C29: % | D29: =EffDisc | E29: =EffDisc | F29: =EffDisc
B30: 1. What a dropout actually costs (unpaid instalments + refunds to full payers)
B31: Dropouts per year | C31: students/yr | D31: =D6*D8 | E31: =E6*E8 | F31: =F6*F8
B32: Avg fee lost per dropout (timing curve × unpaid instalments / pro-rata refund) | C32: ₹/dropout | D32: =SUMPRODUCT(DropTiming,D7*((1-D9)*(1-(INT((DropMonth-1)*D10/CourseMonths)+1)/D10)+D9*D11*DropRemain)) | E32: =SUMPRODUCT(DropTiming,E7*((1-E9)*(1-(INT((DropMonth-1)*E10/CourseMonths)+1)/E10)+E9*E11*DropRemain)) | F32: =SUMPRODUCT(DropTiming,F7*((1-F9)*(1-(INT((DropMonth-1)*F10/CourseMonths)+1)/F10)+F9*F11*DropRemain))
B33: Fee lost to dropouts per year (no platform) | C33: ₹/yr | D33: =D31*D32 | E33: =E31*E32 | F33: =F31*F32
B34: 2. Prevention funnel (replaces the guide's flat 25%)
B35: Blended recall (minors: academic model + rules; 18+: full ML) | C35: % | D35: =D13*D14+(1-D13)*D15 | E35: =E13*E14+(1-E13)*E15 | F35: =F13*F14+(1-F13)*F15
B36: Share of dropouts after the 'blind' months (enough test data to flag) | C36: % | D36: =SUMPRODUCT(DropTiming*(DropMonth>D12)) | E36: =SUMPRODUCT(DropTiming*(DropMonth>E12)) | F36: =SUMPRODUCT(DropTiming*(DropMonth>F12))
B37: Effective dropout reduction = recall × action × RCT effect × catchable | C37: % | D37: =D35*D17*D18*D36 | E37: =E35*E17*E18*E36 | F37: =F35*F17*F18*F36
B38: Dropouts prevented per year | C38: students/yr | D38: =D31*D37 | E38: =E31*E37 | F38: =F31*F37
B39: Fee saved per prevented dropout (catchable months only) | C39: ₹/student | D39: =IF(D36>0,SUMPRODUCT(DropTiming*(DropMonth>D12)*D7*((1-D9)*(1-(INT((DropMonth-1)*D10/CourseMonths)+1)/D10)+D9*D11*DropRemain))/D36,0) | E39: =IF(E36>0,SUMPRODUCT(DropTiming*(DropMonth>E12)*E7*((1-E9)*(1-(INT((DropMonth-1)*E10/CourseMonths)+1)/E10)+E9*E11*DropRemain))/E36,0) | F39: =IF(F36>0,SUMPRODUCT(DropTiming*(DropMonth>F12)*F7*((1-F9)*(1-(INT((DropMonth-1)*F10/CourseMonths)+1)/F10)+F9*F11*DropRemain))/F36,0)
B40: 3. Value to the institute (₹/yr)
B41: Fees retained | C41: ₹/yr | D41: =D38*D39 | E41: =E38*E39 | F41: =F38*F39
...

Sheet Unit_Econ
A1: Unit economics per institute (live scenario)
A2: LTV uses a seasonal survival curve (monthly churn + a renewal spike that applies only after the customer has paid MinRenewTenure months), discounted, capped at 60 months. Payback = 61 means 'not within 60 months'. Undiscounted LTV and simple payback are shown too, because peers quote those.
B4: Line | C4: Unit | D4: Small (<250) | E4: Mid (250-800) | F4: Large (>800) | H4: Guide's naive unit economics | I4: Value
B5: Inputs (from Assumptions / Pricing / COGS_Build) | H5: Revenue per institute per month | I5: =G_Students*G_Price
B6: Students per institute | C6: students | D6: =Students_S | E6: =Students_M | F6: =Students_L | H6: Contribution per month | I6: =G_Students*G_Price-G_Students*G_Infra-G_Support
B7: List price per active student per month | C7: Rs/student/month | D7: =ListPrice | E7: =ListPrice | F7: =ListPrice | H7: CAC + onboarding | I7: =G_CAC+G_Onboard
B8: Minimum monthly fee per institute | C8: Rs/month | D8: =MinFee | E8: =MinFee | F8: =MinFee | H8: Payback (months) | I8: =(G_CAC+G_Onboard)/(G_Students*G_Price-G_Students*G_Infra-G_Support)
B9: Bad debt / uncollected billing | C9: % | D9: =BadDebt | E9: =BadDebt | F9: =BadDebt | H9: LTV = contribution ÷ churn | I9: =(G_Students*G_Price-G_Students*G_Infra-G_Support)/G_Churn
B10: Payment collection cost (blended) | C10: % of revenue | D10: =GatewayFee | E10: =GatewayFee | F10: =GatewayFee | H10: LTV ÷ (CAC + onboarding) | I10: =((G_Students*G_Price-G_Students*G_Infra-G_Support)/G_Churn)/(G_CAC+G_Onboard)
B11: Monthly logo churn for monthly payers | C11: %/month | D11: =ChurnInSeason | E11: =ChurnInSeason | F11: =ChurnInSeason
B12: Share of institutes choosing annual prepay | C12: % | D12: =PrepayUptake | E12: =PrepayUptake | F12: =PrepayUptake
B13: Non-renewal at session end (annual) | C13: % of logos | D13: =RenewalSpike | E13: =RenewalSpike | F13: =RenewalSpike | H13: Break-even scale, steady state (no new sales; fixed team ÷ Mid contribution) | I13: Value
B14: Customer-success / onboarding exec monthly CTC | C14: Rs/month | D14: =CSM_CTC | E14: =CSM_CTC | F14: =CSM_CTC | H14: Fixed team + tools cost per month | I14: =Founders*FounderStipend+EngineersY1*EngineerCTC+ToolsOpex
B15: Institutes per CSM | C15: institutes | D15: =InstPerCSM | E15: =InstPerCSM | F15: =InstPerCSM | H15: Mid-institute avg monthly contribution | I15: =E37
B16: Field sales rep monthly CTC (incl. fuel) | C16: Rs/month | D16: =RepCTC | E16: =RepCTC | F16: =RepCTC | H16: Institutes needed to cover fixed cost | I16: =IF(I15>0,I14/I15,0)
B17: Rep intercity travel + demo material per month | C17: Rs/month | D17: =RepTravel | E17: =RepTravel | F17: =RepTravel | H17: …equivalent active students | I17: =I16*Students_M
B18: Pilots started per rep per month (yearly avg) | C18: pilots | D18: =PilotsPerRepMonth | E18: =PilotsPerRepMonth | F18: =PilotsPerRepMonth | H18: Paid institutes one rep adds per month | I18: =PilotsPerRepMonth*PilotConv
B19: Pilot-to-paid conversion | C19: % | D19: =PilotConv | E19: =PilotConv | F19: =PilotConv
B20: Free pilot length | C20: months | D20: =PilotMonths | E20: =PilotMonths | F20: =PilotMonths | H20: Hiring plan, cohorts, P&L, cash and funding need: see the Projection tab.
B21: Retro-pilot setup (import last year's Excel; show who left) | C21: Rs per pilot | D21: =PilotSetupCost | E21: =PilotSetupCost | F21: =PilotSetupCost
B22: Onboarding cost per institute (mid) | C22: Rs | D22: =OnboardBase | E22: =OnboardBase | F22: =OnboardBase
B23: Onboarding cost multiplier | C23: x | D23: =OnboardMult_S | E23: =OnboardMult_M | F23: =OnboardMult_L
B24: Marketing spend per paid institute | C24: Rs | D24: =MarketingPerPaid | E24: =MarketingPerPaid | F24: =MarketingPerPaid
B25: Sales overhead loading on rep cost (manager, incentives, recruiting, tools) | C25: % of rep cost | D25: =SalesOverheadPct | E25: =SalesOverheadPct | F25: =SalesOverheadPct
B26: Months a customer must have paid before the first renewal decision | C26: months | D26: =MinRenewTenure | E26: =MinRenewTenure | F26: =MinRenewTenure
B27: Channel-partner commission (share of year-1 revenue) | C27: % of year-1 revenue | D27: =ChannelCommission | E27: =ChannelCommission | F27: =ChannelCommission
B28: Effective discount (Pricing) | C28: % | D28: =EffDisc | E28: =EffDisc | F28: =EffDisc
B29: Variable COGS per student-month (COGS_Build) | C29: ₹/student/month | D29: =COGS_PerStudent | E29: =COGS_PerStudent | F29: =COGS_PerStudent
B30: Fixed COGS per institute-month (COGS_Build) | C30: ₹/month | D30: =COGS_FixedInst | E30: =COGS_FixedInst | F30: =COGS_FixedInst
B31: 1. Year-1 economics per institute (before churn)
B32: Collected revenue, first 12 paid months (ex-GST, after bad debt) | C32: ₹/yr | D32: =SUM(D61:D72) | E32: =SUM(E61:E72) | F32: =SUM(F61:F72)
B33: Average monthly revenue | C33: ₹/month | D33: =D32/12 | E33: =E32/12 | F33: =F32/12
B34: COGS, first 12 months (students × seasonality × COGS + fixed + gateway) | C34: ₹/yr | D34: =D6*D29*SUM(Seasonality!$C$37:$C$48)+12*D30+D10*D32 | E34: =E6*E29*SUM(Seasonality!$C$37:$C$48)+12*E30+E10*E32 | F34: =F6*F29*SUM(Seasonality!$C$37:$C$48)+12*F30+F10*F32
B35: Product gross margin (before customer-success staff) | C35: % | D35: =IF(D32>0,(D32-D34)/D32,0) | E35: =IF(E32>0,(E32-E34)/E32,0) | F35: =IF(F32>0,(F32-F34)/F32,0)
B36: Customer-success cost per institute | C36: ₹/month | D36: =D14/D15 | E36: =E14/E15 | F36: =F14/F15
B37: Average monthly contribution (after COGS + support) | C37: ₹/month | D37: =SUM(D121:D132)/12 | E37: =SUM(E121:E132)/12 | F37: =SUM(F121:F132)/12
B38: Contribution margin (after support: the PS's definition, a peer's 'gross margin') | C38: % | D38: =IF(D33>0,D37/D33,0) | E38: =IF(E33>0,E37/E33,0) | F38: =IF(F33>0,F37/F33,0)
B39: 2. Cost to acquire one paying institute
B40: Sales cost per pilot started (rep CTC + travel, loaded with overhead, ÷ pilots) | C40: ₹ | D40: =(D16+D17)*(1+D25)/D18 | E40: =(E16+E17)*(1+E25)/E18 | F40: =(F16+F17)*(1+F25)/F18
B41: Onboarding cost (data migration + training) | C41: ₹ | D41: =D22*D23 | E41: =E22*E23 | F41: =F22*F23
...

Sheet Projection
A1: 3-year projection — live scenario: sales capacity → cohorts → P&L → cash → funding ask
A2: Months run April to March. Revenue starts after the free pilot. New institutes are capped by the addressable market. Rows 6-80 (inputs and per-institute vectors) are grouped: use the +/- in the left margin.
B3: Scenario (1 = Bear, 2 = Base, 3 = Bull) | D3: =Scenario
B5: Inputs used (linked from Assumptions; Bear / Base / Bull chosen by the scenario)
B6: Students per institute - Small | C6: students | D6: =Students_S
B7: Students per institute - Mid | C7: students | D7: =Students_M
B8: Students per institute - Large | C8: students | D8: =Students_L
B9: Onboarding cost multiplier - Small | C9: x | D9: =OnboardMult_S
B10: Onboarding cost multiplier - Mid | C10: x | D10: =OnboardMult_M
B11: Onboarding cost multiplier - Large | C11: x | D11: =OnboardMult_L
B12: Share of new institutes that are Small | C12: % of new logos | D12: =SegMix_S
B13: Share of new institutes that are Mid | C13: % of new logos | D13: =SegMix_M
B14: Share of new institutes that are Large | C14: % of new logos | D14: =SegMix_L
B15: List price per active student per month | C15: Rs/student/month | D15: =ListPrice
B16: Minimum monthly fee per institute | C16: Rs/month | D16: =MinFee
B17: Average negotiated discount off list | C17: % | D17: =NegotiationDisc
B18: Share of institutes choosing annual prepay | C18: % | D18: =PrepayUptake
B19: Annual prepay discount | C19: % | D19: =PrepayDisc
B20: Bad debt / uncollected billing | C20: % | D20: =BadDebt
B21: Payment collection cost (blended) | C21: % of revenue | D21: =GatewayFee
B22: AI parent reports per student per month | C22: reports | D22: =ReportsPerStudentMonth
B23: LLM input tokens per report | C23: tokens | D23: =TokensInPerReport
B24: LLM output tokens per report | C24: tokens | D24: =TokensOutPerReport
B25: LLM input price (hosted) | C25: Rs per 1M tokens | D25: =LLMPriceIn
B26: LLM output price (hosted) | C26: Rs per 1M tokens | D26: =LLMPriceOut
B27: WhatsApp utility messages per student per month | C27: messages | D27: =WAMsgsPerStudentMonth
B28: WhatsApp utility message price (India) | C28: Rs/message | D28: =WAPricePerMsg
B29: Compute + storage + backups per student | C29: Rs/student/month | D29: =ComputePerStudentMonth
B30: Consent OTP + verification per student | C30: Rs/student/yr | D30: =ConsentCostPerStudentYear
B31: App server + managed Postgres + backups per stack | C31: Rs/month | D31: =ServerCostMonth
B32: WhatsApp BSP platform fee per stack | C32: Rs/month | D32: =BSPFeeMonth
B33: Institutes sharing one server stack | C33: institutes | D33: =InstPerStack
B34: DPDP compliance cost per institute | C34: Rs/month | D34: =CompliancePerInstMonth
B35: Customer-success / onboarding exec monthly CTC | C35: Rs/month | D35: =CSM_CTC
B36: Institutes per CSM | C36: institutes | D36: =InstPerCSM
B37: Field sales rep monthly CTC (incl. fuel) | C37: Rs/month | D37: =RepCTC
B38: Rep intercity travel + demo material per month | C38: Rs/month | D38: =RepTravel
B39: Sales overhead loading on rep cost (manager, incentives, recruiting, tools) | C39: % of rep cost | D39: =SalesOverheadPct
B40: Pilots started per rep per month (yearly avg) | C40: pilots | D40: =PilotsPerRepMonth
B41: Pilot-to-paid conversion | C41: % | D41: =PilotConv
...

Sheet Scenarios
A1: Scenarios — honest model vs the guide's naive model
A2: Bear / Base / Bull flex only the 13 scenario drivers (Assumptions column N); every other input stays at Base. Stress flexes ALL inputs to their worst at once: a survival test, not a forecast. Mid institute = 400 students. Always shown side by side, whatever the Cover selector says.
A4: Metric (Mid institute) | B4: Unit | C4: Guide (naive) | D4: Bear | E4: Base | F4: Bull | G4: Stress (all inputs worst)
A5: Effective dropout reduction | B5: % | C5: =Assumptions!$E$90 | D5: =Engine!$H$84 | E5: =Engine!$K$84 | F5: =Engine!$N$84 | G5: =Engine!$Q$84
A6: Dropouts prevented per year | B6: students | C6: =Institute_ROI!$E$67 | D6: =Engine!$H$85 | E6: =Engine!$K$85 | F6: =Engine!$N$85 | G6: =Engine!$Q$85
A7: Fee lost per dropout | B7: ₹ | C7: =G_RemainingFee | D7: =Engine!$H$80 | E7: =Engine!$K$80 | F7: =Engine!$N$80 | G7: =Engine!$Q$80
A8: Fees retained per year | B8: ₹/yr | C8: =Institute_ROI!$E$68 | D8: =Engine!$H$87 | E8: =Engine!$K$87 | F8: =Engine!$N$87 | G8: =Engine!$Q$87
A9: Total value to institute | B9: ₹/yr | C9: =Institute_ROI!$E$68 | D9: =Engine!$H$90 | E9: =Engine!$K$90 | F9: =Engine!$N$90 | G9: =Engine!$Q$90
A10: Total cost to institute (fee + GST + mentor time) | B10: ₹/yr | C10: =Institute_ROI!$E$69 | D10: =Engine!$H$96 | E10: =Engine!$K$96 | F10: =Engine!$N$96 | G10: =Engine!$Q$96
A11: Institute ROI, all benefits | B11: x | C11: =Institute_ROI!$E$70 | D11: =Engine!$H$98 | E11: =Engine!$K$98 | F11: =Engine!$N$98 | G11: =Engine!$Q$98
A12: Institute ROI, hard benefits (fees + staff time) | B12: x | C12: =Institute_ROI!$E$70 | D12: =Engine!$H$100 | E12: =Engine!$K$100 | F12: =Engine!$N$100 | G12: =Engine!$Q$100
A13: Institute ROI, fees only | B13: x | C13: =Institute_ROI!$E$70 | D13: =Engine!$H$99 | E13: =Engine!$K$99 | F13: =Engine!$N$99 | G13: =Engine!$Q$99
A14: Break-even students saved per year | B14: students | C14: =Institute_ROI!$E$71 | D14: =Engine!$H$101 | E14: =Engine!$K$101 | F14: =Engine!$N$101 | G14: =Engine!$Q$101
A15: Avg monthly revenue per institute | B15: ₹/month | C15: =Unit_Econ!$I$5 | D15: =Engine!$H$108 | E15: =Engine!$K$108 | F15: =Engine!$N$108 | G15: =Engine!$Q$108
A16: Avg monthly contribution | B16: ₹/month | C16: =Unit_Econ!$I$6 | D16: =Engine!$H$112 | E16: =Engine!$K$112 | F16: =Engine!$N$112 | G16: =Engine!$Q$112
A17: CAC: sales + marketing per paying institute | B17: ₹ | C17: =G_CAC | D17: =Engine!$H$117 | E17: =Engine!$K$117 | F17: =Engine!$N$117 | G17: =Engine!$Q$117
A18: Fully loaded acquisition cost | B18: ₹ | C18: =Unit_Econ!$I$7 | D18: =Engine!$H$118 | E18: =Engine!$K$118 | F18: =Engine!$N$118 | G18: =Engine!$Q$118
A19: Annual logo retention | B19: % | C19: =(1-G_Churn)^12 | D19: =Engine!$H$121 | E19: =Engine!$K$121 | F19: =Engine!$N$121 | G19: =Engine!$Q$121
A20: LTV, discounted | B20: ₹ | C20: =Unit_Econ!$I$9 | D20: =Engine!$H$123 | E20: =Engine!$K$123 | F20: =Engine!$N$123 | G20: =Engine!$Q$123
A21: LTV ÷ acquisition cost, discounted | B21: x | C21: =Unit_Econ!$I$10 | D21: =Engine!$H$124 | E21: =Engine!$K$124 | F21: =Engine!$N$124 | G21: =Engine!$Q$124
A22: LTV ÷ acquisition cost, undiscounted (peer convention) | B22: x | C22: =Unit_Econ!$I$10 | D22: =Engine!$H$128 | E22: =Engine!$K$128 | F22: =Engine!$N$128 | G22: =Engine!$Q$128
A23: Payback, survival-weighted and discounted | B23: months | C23: =Unit_Econ!$I$8 | D23: =Engine!$H$125 | E23: =Engine!$K$125 | F23: =Engine!$N$125 | G23: =Engine!$Q$125
A24: Payback, simple | B24: months | C24: =Unit_Econ!$I$8 | D24: =Engine!$H$126 | E24: =Engine!$K$126 | F24: =Engine!$N$126 | G24: =Engine!$Q$126
A27: By segment
A28: Institute ROI, all benefits | D28: Bear | E28: Base | F28: Bull
A29: Small (<250) | D29: =Engine!$G$98 | E29: =Engine!$J$98 | F29: =Engine!$M$98
A30: Mid (250-800) | D30: =Engine!$H$98 | E30: =Engine!$K$98 | F30: =Engine!$N$98
A31: Large (>800) | D31: =Engine!$I$98 | E31: =Engine!$L$98 | F31: =Engine!$O$98
A34: LTV ÷ acquisition cost (field sales) | D34: Bear | E34: Base | F34: Bull
A35: Small (<250) | D35: =Engine!$G$124 | E35: =Engine!$J$124 | F35: =Engine!$M$124
A36: Mid (250-800) | D36: =Engine!$H$124 | E36: =Engine!$K$124 | F36: =Engine!$N$124
A37: Large (>800) | D37: =Engine!$I$124 | E37: =Engine!$L$124 | F37: =Engine!$O$124
A40: LTV ÷ acquisition cost (channel partner) | D40: Bear | E40: Base | F40: Bull
A41: Small (<250) | D41: =Engine!$G$130 | E41: =Engine!$J$130 | F41: =Engine!$M$130
A42: Mid (250-800) | D42: =Engine!$H$130 | E42: =Engine!$K$130 | F42: =Engine!$N$130
A43: Large (>800) | D43: =Engine!$I$130 | E43: =Engine!$L$130 | F43: =Engine!$O$130
A46: Payback (months) | D46: Bear | E46: Base | F46: Bull
A47: Small (<250) | D47: =Engine!$G$125 | E47: =Engine!$J$125 | F47: =Engine!$M$125
A48: Mid (250-800) | D48: =Engine!$H$125 | E48: =Engine!$K$125 | F48: =Engine!$N$125
A49: Large (>800) | D49: =Engine!$I$125 | E49: =Engine!$L$125 | F49: =Engine!$O$125
...

Sheet Sensitivity
A1: Sensitivity — what actually moves the answer
A2: Tornado: one input at a time moved to its Bear / Bull value, all else Base (Mid institute). Grids follow the live scenario.
A4: Input | B4: Bear value | C4: Bull value | D4: ROI @ Bear | E4: ROI @ Bull | F4: ROI swing | G4: LTV/CAC @ Bear | H4: LTV/CAC @ Bull | I4: LTV/CAC swing
A5: BASE (all inputs Base) | D5: =Engine!$K$98 | E5: =Engine!$K$98 | G5: =Engine!$K$124 | H5: =Engine!$K$124
A6: List price per active student per month | B6: =Assumptions!$D$38 | C6: =Assumptions!$F$38 | D6: =Engine!$S$98 | E6: =Engine!$T$98 | F6: =ABS(E6-D6) | G6: =Engine!$S$124 | H6: =Engine!$T$124 | I6: =ABS(H6-G6)
A7: Annual fee per student - Mid | B7: =Assumptions!$D$10 | C7: =Assumptions!$F$10 | D7: =Engine!$U$98 | E7: =Engine!$V$98 | F7: =ABS(E7-D7) | G7: =Engine!$U$124 | H7: =Engine!$V$124 | I7: =ABS(H7-G7)
A8: Mid-session dropout/default rate | B8: =Assumptions!$D$16 | C8: =Assumptions!$F$16 | D8: =Engine!$W$98 | E8: =Engine!$X$98 | F8: =ABS(E8-D8) | G8: =Engine!$W$124 | H8: =Engine!$X$124 | I8: =ABS(H8-G8)
A9: Share of students paying full fee upfront | B9: =Assumptions!$D$17 | C9: =Assumptions!$F$17 | D9: =Engine!$Y$98 | E9: =Engine!$Z$98 | F9: =ABS(E9-D9) | G9: =Engine!$Y$124 | H9: =Engine!$Z$124 | I9: =ABS(H9-G9)
A10: Instalments per year for non-upfront payers | B10: =Assumptions!$D$18 | C10: =Assumptions!$F$18 | D10: =Engine!$AA$98 | E10: =Engine!$AB$98 | F10: =ABS(E10-D10) | G10: =Engine!$AA$124 | H10: =Engine!$AB$124 | I10: =ABS(H10-G10)
A11: Dropout reduction among flagged students given outreach (RCT) | B11: =Assumptions!$D$28 | C11: =Assumptions!$F$28 | D11: =Engine!$AC$98 | E11: =Engine!$AD$98 | F11: =ABS(E11-D11) | G11: =Engine!$AC$124 | H11: =Engine!$AD$124 | I11: =ABS(H11-G11)
A12: Model recall on minors (academic-support + rules) | B12: =Assumptions!$D$24 | C12: =Assumptions!$F$24 | D12: =Engine!$AE$98 | E12: =Engine!$AF$98 | F12: =ABS(E12-D12) | G12: =Engine!$AE$124 | H12: =Engine!$AF$124 | I12: =ABS(H12-G12)
A13: Precision of at-risk flag | B13: =Assumptions!$D$26 | C13: =Assumptions!$F$26 | D13: =Engine!$AG$98 | E13: =Engine!$AH$98 | F13: =ABS(E13-D13) | G13: =Engine!$AG$124 | H13: =Engine!$AH$124 | I13: =ABS(H13-G13)
A14: Mentor minutes per intervention | B14: =Assumptions!$D$33 | C14: =Assumptions!$F$33 | D14: =Engine!$AI$98 | E14: =Engine!$AJ$98 | F14: =ABS(E14-D14) | G14: =Engine!$AI$124 | H14: =Engine!$AJ$124 | I14: =ABS(H14-G14)
A15: Months before the model can flag (no test data yet) | B15: =Assumptions!$D$21 | C15: =Assumptions!$F$21 | D15: =Engine!$AK$98 | E15: =Engine!$AL$98 | F15: =ABS(E15-D15) | G15: =Engine!$AK$124 | H15: =Engine!$AL$124 | I15: =ABS(H15-G15)
A16: Admissions uplift next session from results/parent trust | B16: =Assumptions!$D$29 | C16: =Assumptions!$F$29 | D16: =Engine!$AM$98 | E16: =Engine!$AN$98 | F16: =ABS(E16-D16) | G16: =Engine!$AM$124 | H16: =Engine!$AN$124 | I16: =ABS(H16-G16)
A17: Share of institutes that reclaim our GST as input credit | B17: =Assumptions!$D$36 | C17: =Assumptions!$F$36 | D17: =Engine!$AO$98 | E17: =Engine!$AP$98 | F17: =ABS(E17-D17) | G17: =Engine!$AO$124 | H17: =Engine!$AP$124 | I17: =ABS(H17-G17)
A18: Monthly logo churn for monthly payers | B18: =Assumptions!$D$74 | C18: =Assumptions!$F$74 | D18: =Engine!$AQ$98 | E18: =Engine!$AR$98 | F18: =ABS(E18-D18) | G18: =Engine!$AQ$124 | H18: =Engine!$AR$124 | I18: =ABS(H18-G18)
A19: Non-renewal at session end (annual) | B19: =Assumptions!$D$75 | C19: =Assumptions!$F$75 | D19: =Engine!$AS$98 | E19: =Engine!$AT$98 | F19: =ABS(E19-D19) | G19: =Engine!$AS$124 | H19: =Engine!$AT$124 | I19: =ABS(H19-G19)
A20: Pilot-to-paid conversion | B20: =Assumptions!$D$68 | C20: =Assumptions!$F$68 | D20: =Engine!$AU$98 | E20: =Engine!$AV$98 | F20: =ABS(E20-D20) | G20: =Engine!$AU$124 | H20: =Engine!$AV$124 | I20: =ABS(H20-G20)
A21: Pilots started per rep per month (yearly avg) | B21: =Assumptions!$D$67 | C21: =Assumptions!$F$67 | D21: =Engine!$AW$98 | E21: =Engine!$AX$98 | F21: =ABS(E21-D21) | G21: =Engine!$AW$124 | H21: =Engine!$AX$124 | I21: =ABS(H21-G21)
A22: Institutes per CSM | B22: =Assumptions!$D$63 | C22: =Assumptions!$F$63 | D22: =Engine!$AY$98 | E22: =Engine!$AZ$98 | F22: =ABS(E22-D22) | G22: =Engine!$AY$124 | H22: =Engine!$AZ$124 | I22: =ABS(H22-G22)
A25: Grid 1 — Institute ROI (Mid, live scenario): list price × effective dropout reduction
A26: Rows: effective reduction · Columns: list price ₹/student/month (blue = grid points)
B27: 20 | C27: 30 | D27: 40 | E27: 50 | F27: 60 | G27: 80
A28: 0.05 | B28: =(Institute_ROI!$E$31*Institute_ROI!$E$39*$A28+Institute_ROI!$E$42+Institute_ROI!$E$43)/(SUMPRODUCT((Institute_ROI!$E$6*Season_Idx*B$27>Institute_ROI!$E$26)*(Institute_ROI!$E$6*Season_Idx*B$27)+(Institute_ROI!$E$6*Season_Idx*B$27<=Institute_ROI!$E$26)*Institute_ROI!$E$26)*(1-Institute_ROI!$E$29)*(1+GST*(1-ITCShare))+Institute_ROI!$E$50) | C28: =(Institute_ROI!$E$31*Institute_ROI!$E$39*$A28+Institute_ROI!$E$42+Institute_ROI!$E$43)/(SUMPRODUCT((Institute_ROI!$E$6*Season_Idx*C$27>Institute_ROI!$E$26)*(Institute_ROI!$E$6*Season_Idx*C$27)+(Institute_ROI!$E$6*Season_Idx*C$27<=Institute_ROI!$E$26)*Institute_ROI!$E$26)*(1-Institute_ROI!$E$29)*(1+GST*(1-ITCShare))+Institute_ROI!$E$50) | D28: =(Institute_ROI!$E$31*Institute_ROI!$E$39*$A28+Institute_ROI!$E$42+Institute_ROI!$E$43)/(SUMPRODUCT((Institute_ROI!$E$6*Season_Idx*D$27>Institute_ROI!$E$26)*(Institute_ROI!$E$6*Season_Idx*D$27)+(Institute_ROI!$E$6*Season_Idx*D$27<=Institute_ROI!$E$26)*Institute_ROI!$E$26)*(1-Institute_ROI!$E$29)*(1+GST*(1-ITCShare))+Institute_ROI!$E$50) | E28: =(Institute_ROI!$E$31*Institute_ROI!$E$39*$A28+Institute_ROI!$E$42+Institute_ROI!$E$43)/(SUMPRODUCT((Institute_ROI!$E$6*Season_Idx*E$27>Institute_ROI!$E$26)*(Institute_ROI!$E$6*Season_Idx*E$27)+(Institute_ROI!$E$6*Season_Idx*E$27<=Institute_ROI!$E$26)*Institute_ROI!$E$26)*(1-Institute_ROI!$E$29)*(1+GST*(1-ITCShare))+Institute_ROI!$E$50) | F28: =(Institute_ROI!$E$31*Institute_ROI!$E$39*$A28+Institute_ROI!$E$42+Institute_ROI!$E$43)/(SUMPRODUCT((Institute_ROI!$E$6*Season_Idx*F$27>Institute_ROI!$E$26)*(Institute_ROI!$E$6*Season_Idx*F$27)+(Institute_ROI!$E$6*Season_Idx*F$27<=Institute_ROI!$E$26)*Institute_ROI!$E$26)*(1-Institute_ROI!$E$29)*(1+GST*(1-ITCShare))+Institute_ROI!$E$50) | G28: =(Institute_ROI!$E$31*Institute_ROI!$E$39*$A28+Institute_ROI!$E$42+Institute_ROI!$E$43)/(SUMPRODUCT((Institute_ROI!$E$6*Season_Idx*G$27>Institute_ROI!$E$26)*(Institute_ROI!$E$6*Season_Idx*G$27)+(Institute_ROI!$E$6*Season_Idx*G$27<=Institute_ROI!$E$26)*Institute_ROI!$E$26)*(1-Institute_ROI!$E$29)*(1+GST*(1-ITCShare))+Institute_ROI!$E$50)
A29: 0.08 | B29: =(Institute_ROI!$E$31*Institute_ROI!$E$39*$A29+Institute_ROI!$E$42+Institute_ROI!$E$43)/(SUMPRODUCT((Institute_ROI!$E$6*Season_Idx*B$27>Institute_ROI!$E$26)*(Institute_ROI!$E$6*Season_Idx*B$27)+(Institute_ROI!$E$6*Season_Idx*B$27<=Institute_ROI!$E$26)*Institute_ROI!$E$26)*(1-Institute_ROI!$E$29)*(1+GST*(1-ITCShare))+Institute_ROI!$E$50) | C29: =(Institute_ROI!$E$31*Institute_ROI!$E$39*$A29+Institute_ROI!$E$42+Institute_ROI!$E$43)/(SUMPRODUCT((Institute_ROI!$E$6*Season_Idx*C$27>Institute_ROI!$E$26)*(Institute_ROI!$E$6*Season_Idx*C$27)+(Institute_ROI!$E$6*Season_Idx*C$27<=Institute_ROI!$E$26)*Institute_ROI!$E$26)*(1-Institute_ROI!$E$29)*(1+GST*(1-ITCShare))+Institute_ROI!$E$50) | D29: =(Institute_ROI!$E$31*Institute_ROI!$E$39*$A29+Institute_ROI!$E$42+Institute_ROI!$E$43)/(SUMPRODUCT((Institute_ROI!$E$6*Season_Idx*D$27>Institute_ROI!$E$26)*(Institute_ROI!$E$6*Season_Idx*D$27)+(Institute_ROI!$E$6*Season_Idx*D$27<=Institute_ROI!$E$26)*Institute_ROI!$E$26)*(1-Institute_ROI!$E$29)*(1+GST*(1-ITCShare))+Institute_ROI!$E$50) | E29: =(Institute_ROI!$E$31*Institute_ROI!$E$39*$A29+Institute_ROI!$E$42+Institute_ROI!$E$43)/(SUMPRODUCT((Institute_ROI!$E$6*Season_Idx*E$27>Institute_ROI!$E$26)*(Institute_ROI!$E$6*Season_Idx*E$27)+(Institute_ROI!$E$6*Season_Idx*E$27<=Institute_ROI!$E$26)*Institute_ROI!$E$26)*(1-Institute_ROI!$E$29)*(1+GST*(1-ITCShare))+Institute_ROI!$E$50) | F29: =(Institute_ROI!$E$31*Institute_ROI!$E$39*$A29+Institute_ROI!$E$42+Institute_ROI!$E$43)/(SUMPRODUCT((Institute_ROI!$E$6*Season_Idx*F$27>Institute_ROI!$E$26)*(Institute_ROI!$E$6*Season_Idx*F$27)+(Institute_ROI!$E$6*Season_Idx*F$27<=Institute_ROI!$E$26)*Institute_ROI!$E$26)*(1-Institute_ROI!$E$29)*(1+GST*(1-ITCShare))+Institute_ROI!$E$50) | G29: =(Institute_ROI!$E$31*Institute_ROI!$E$39*$A29+Institute_ROI!$E$42+Institute_ROI!$E$43)/(SUMPRODUCT((Institute_ROI!$E$6*Season_Idx*G$27>Institute_ROI!$E$26)*(Institute_ROI!$E$6*Season_Idx*G$27)+(Institute_ROI!$E$6*Season_Idx*G$27<=Institute_ROI!$E$26)*Institute_ROI!$E$26)*(1-Institute_ROI!$E$29)*(1+GST*(1-ITCShare))+Institute_ROI!$E$50)
A30: 0.11 | B30: =(Institute_ROI!$E$31*Institute_ROI!$E$39*$A30+Institute_ROI!$E$42+Institute_ROI!$E$43)/(SUMPRODUCT((Institute_ROI!$E$6*Season_Idx*B$27>Institute_ROI!$E$26)*(Institute_ROI!$E$6*Season_Idx*B$27)+(Institute_ROI!$E$6*Season_Idx*B$27<=Institute_ROI!$E$26)*Institute_ROI!$E$26)*(1-Institute_ROI!$E$29)*(1+GST*(1-ITCShare))+Institute_ROI!$E$50) | C30: =(Institute_ROI!$E$31*Institute_ROI!$E$39*$A30+Institute_ROI!$E$42+Institute_ROI!$E$43)/(SUMPRODUCT((Institute_ROI!$E$6*Season_Idx*C$27>Institute_ROI!$E$26)*(Institute_ROI!$E$6*Season_Idx*C$27)+(Institute_ROI!$E$6*Season_Idx*C$27<=Institute_ROI!$E$26)*Institute_ROI!$E$26)*(1-Institute_ROI!$E$29)*(1+GST*(1-ITCShare))+Institute_ROI!$E$50) | D30: =(Institute_ROI!$E$31*Institute_ROI!$E$39*$A30+Institute_ROI!$E$42+Institute_ROI!$E$43)/(SUMPRODUCT((Institute_ROI!$E$6*Season_Idx*D$27>Institute_ROI!$E$26)*(Institute_ROI!$E$6*Season_Idx*D$27)+(Institute_ROI!$E$6*Season_Idx*D$27<=Institute_ROI!$E$26)*Institute_ROI!$E$26)*(1-Institute_ROI!$E$29)*(1+GST*(1-ITCShare))+Institute_ROI!$E$50) | E30: =(Institute_ROI!$E$31*Institute_ROI!$E$39*$A30+Institute_ROI!$E$42+Institute_ROI!$E$43)/(SUMPRODUCT((Institute_ROI!$E$6*Season_Idx*E$27>Institute_ROI!$E$26)*(Institute_ROI!$E$6*Season_Idx*E$27)+(Institute_ROI!$E$6*Season_Idx*E$27<=Institute_ROI!$E$26)*Institute_ROI!$E$26)*(1-Institute_ROI!$E$29)*(1+GST*(1-ITCShare))+Institute_ROI!$E$50) | F30: =(Institute_ROI!$E$31*Institute_ROI!$E$39*$A30+Institute_ROI!$E$42+Institute_ROI!$E$43)/(SUMPRODUCT((Institute_ROI!$E$6*Season_Idx*F$27>Institute_ROI!$E$26)*(Institute_ROI!$E$6*Season_Idx*F$27)+(Institute_ROI!$E$6*Season_Idx*F$27<=Institute_ROI!$E$26)*Institute_ROI!$E$26)*(1-Institute_ROI!$E$29)*(1+GST*(1-ITCShare))+Institute_ROI!$E$50) | G30: =(Institute_ROI!$E$31*Institute_ROI!$E$39*$A30+Institute_ROI!$E$42+Institute_ROI!$E$43)/(SUMPRODUCT((Institute_ROI!$E$6*Season_Idx*G$27>Institute_ROI!$E$26)*(Institute_ROI!$E$6*Season_Idx*G$27)+(Institute_ROI!$E$6*Season_Idx*G$27<=Institute_ROI!$E$26)*Institute_ROI!$E$26)*(1-Institute_ROI!$E$29)*(1+GST*(1-ITCShare))+Institute_ROI!$E$50)
