Workbook
Name Scenario: Cover!$C$6
Name Students_S: Assumptions!$G$6
Name Students_M: Assumptions!$G$7
Name Students_L: Assumptions!$G$8
Name Fee_S: Assumptions!$G$9
Name Fee_M: Assumptions!$G$10
Name Fee_L: Assumptions!$G$11
Name OnboardMult_S: Assumptions!$G$12
Name OnboardMult_M: Assumptions!$G$13
Name OnboardMult_L: Assumptions!$G$14
Name DropoutRate: Assumptions!$G$16
Name UpfrontShare: Assumptions!$G$17
Name NInstalments: Assumptions!$G$18
Name RefundEnforced: Assumptions!$G$19
Name CourseMonths: Assumptions!$G$20
Name BlindMonths: Assumptions!$G$21
Name Preventable: Assumptions!$G$22
Name MinorShare: Assumptions!$G$23
Name Recall_Minor: Assumptions!$G$24
Name Recall_Adult: Assumptions!$G$25
Name Precision: Assumptions!$G$26
Name ActionRate: Assumptions!$G$27
Name InterventionSuccess: Assumptions!$G$28
Name AdmissionUplift: Assumptions!$G$29
Name MarginExtraAdmission: Assumptions!$G$30
Name StaffHoursSaved: Assumptions!$G$31
Name StaffHourCost: Assumptions!$G$32
Name InterventionMinutes: Assumptions!$G$33
Name MentorHourCost: Assumptions!$G$34
Name GST: Assumptions!$G$35
Name ITCShare: Assumptions!$G$36
Name ListPrice: Assumptions!$G$38
Name CompetitorAnchor: Assumptions!$G$39
Name CompetitorAnchorHigh: Assumptions!$G$40
Name MinFee: Assumptions!$G$41
Name NegotiationDisc: Assumptions!$G$42
Name PrepayUptake: Assumptions!$G$43
Name PrepayDisc: Assumptions!$G$44
Name BadDebt: Assumptions!$G$45
Name GatewayFee: Assumptions!$G$46
Name ReportsPerStudentMonth: Assumptions!$G$48
Name TokensInPerReport: Assumptions!$G$49
Name TokensOutPerReport: Assumptions!$G$50
Name LLMPriceIn: Assumptions!$G$51
Name LLMPriceOut: Assumptions!$G$52
Name WAMsgsPerStudentMonth: Assumptions!$G$53
Name WAPricePerMsg: Assumptions!$G$54
Name ComputePerStudentMonth: Assumptions!$G$55
Name ConsentCostPerStudentYear: Assumptions!$G$56
Name ServerCostMonth: Assumptions!$G$57
Name BSPFeeMonth: Assumptions!$G$58
Name InstPerStack: Assumptions!$G$59
Name CompliancePerInstMonth: Assumptions!$G$60
Name CSM_CTC: Assumptions!$G$62
Name InstPerCSM: Assumptions!$G$63
Name RepCTC: Assumptions!$G$64
Name RepTravel: Assumptions!$G$65
Name PilotsPerRepMonth: Assumptions!$G$66
Name PilotConv: Assumptions!$G$67
Name PilotMonths: Assumptions!$G$68

Sheet Cover
A1: The Data Moat — Financial Model
A2: Institute Intelligence Platform · Nextute × Finance Club IIT Patna, Case B · R1-v1.0 · 2026-10-20
B6: SCENARIO (1 = Bear, 2 = Base, 3 = Bull) → | C6: 2 | D6: =CHOOSE(Scenario,"Bear","Base","Bull")
B7: Model checks | C7: =IF(ErrorCount=0,"ALL CHECKS PASS","ERRORS: "&ErrorCount) | D7: ="Warnings to discuss: "&WarningCount
B9: Headline (Mid institute, 400 students, live scenario) | C9: Our model | D9: Guide (naive)
B10: Effective dropout reduction | C10: =Institute_ROI!E37 | D10: =G_Prevent
B11: Dropouts prevented per year | C11: =Institute_ROI!E38 | D11: =Institute_ROI!$E$65
B12: Institute ROI (all benefits) | C12: =Institute_ROI!E53 | D12: =Institute_ROI!$E$68
B13: Institute ROI (fees only) | C13: =Institute_ROI!E54 | D13: =Institute_ROI!$E$68
B14: Break-even: students to save per year | C14: =Institute_ROI!E55 | D14: =Institute_ROI!$E$69
B15: Extra admissions needed to break even (after fees + staff time) | C15: =Institute_ROI!E58 | D15: n/a
B16: Platform cost as % of a student's fee | C16: =Institute_ROI!E60 | D16: =G_Price*G_Months/Fee_M
B17: Avg monthly revenue per institute | C17: =Unit_Econ!E30 | D17: =Unit_Econ!$I$5
B18: Contribution margin | C18: =Unit_Econ!E35 | D18: =Unit_Econ!$I$6/Unit_Econ!$I$5
B19: Fully loaded acquisition cost | C19: =Unit_Econ!E41 | D19: =Unit_Econ!$I$7
B20: LTV | C20: =Unit_Econ!E48 | D20: =Unit_Econ!$I$9
B21: LTV ÷ acquisition cost | C21: =Unit_Econ!E49 | D21: =Unit_Econ!$I$10
B22: Payback (months) | C22: =Unit_Econ!E50 | D22: =Unit_Econ!$I$8
B23: Institutes needed to cover fixed team cost | C23: =Unit_Econ!I16 | D23: n/a
B25: Colour code
B26: Blue text | C26: Input — edit only these (Assumptions D:F, Seasonality, grid points, Scenario)
B27: Black text | C27: Formula
B28: Green text | C28: Link from another sheet
B29: Yellow fill | C29: Key lever / live value
B30: Green fill | C30: Key output
B32: How to use
B33: 1 | C33: Pick a scenario in C6. Everything recalculates; Scenarios and Sensitivity always show all three.
B34: 2 | C34: Change an input on Assumptions (Bear/Base/Bull) — never type over a formula.
B35: 3 | C35: Cover C7 must say ALL CHECKS PASS before you quote any number.
B36: 4 | C36: To rebuild from the CSVs: python build_model.py (Financial_Model folder).
B38: Evidence labels | C38: Researched/Public = sourced (see Sources) · Guide = case brief · Assumption = unverified · Structural = modelling convention
B39: Scope | C39: Round 1: Pricing, COGS, Institute ROI, Unit economics, Scenarios, Sensitivity. Round 2 adds cohorts, hiring plan, 3-year P&L, cash and funding need.

Sheet Assumptions
A1: Assumptions — every input in the model lives here
A2: Blue = input you may edit (Bear / Base / Bull). Live = CHOOSE(Scenario, Bear, Base, Bull). Bear = worst case for OUR business. Type: Researched/Public = sourced · Guide = case brief · Assumption = unverified · Structural = modelling convention.
A4: Name (named range → Live) | B4: Input | C4: Unit | D4: Bear | E4: Base | F4: Bull | G4: LIVE | H4: Type | I4: Confidence | J4: Source | K4: Note | L4: Pct out of [0,1] | M4: Live outside Bear–Bull
A5: Segments
A6: Students_S | B6: Students per institute - Small | C6: students | D6: 180 | E6: 180 | F6: 180 | G6: =CHOOSE(Scenario,D6,E6,F6) | H6: Assumption | I6: M | J6: Case brief range 150-2000; our cut <250 | K6: Segment midpoint | L6: 0 | M6: =IF(AND(G6>=MIN(D6,F6),G6<=MAX(D6,F6)),0,1)
A7: Students_M | B7: Students per institute - Mid | C7: students | D7: 400 | E7: 400 | F7: 400 | G7: =CHOOSE(Scenario,D7,E7,F7) | H7: Guide | I7: M | J7: Case brief baseline 400 | L7: 0 | M7: =IF(AND(G7>=MIN(D7,F7),G7<=MAX(D7,F7)),0,1)
A8: Students_L | B8: Students per institute - Large | C8: students | D8: 1200 | E8: 1200 | F8: 1200 | G8: =CHOOSE(Scenario,D8,E8,F8) | H8: Assumption | I8: M | J8: Case brief range 150-2000; our cut >800 | L8: 0 | M8: =IF(AND(G8>=MIN(D8,F8),G8<=MAX(D8,F8)),0,1)
A9: Fee_S | B9: Annual fee per student - Small | C9: Rs/yr | D9: 50000 | E9: 65000 | F9: 80000 | G9: =CHOOSE(Scenario,D9,E9,F9) | H9: Researched | I9: L | J9: R2: Vedantu Gaya 1-yr Rs50-56k; Rupantri Muzaffarpur Rs55-60k; GOAL Patna Rs51-99k (research/R2_R3) | K9: Size-to-fee mapping is our assumption | L9: 0 | M9: =IF(AND(G9>=MIN(D9,F9),G9<=MAX(D9,F9)),0,1)
A10: Fee_M | B10: Annual fee per student - Mid | C10: Rs/yr | D10: 70000 | E10: 95000 | F10: 120000 | G10: =CHOOSE(Scenario,D10,E10,F10) | H10: Researched | I10: L | J10: R2: GOAL Patna 1-yr Rs1.2L; Vedantu Patna Rs95k; Pathshala Lucknow ~Rs82.5k; Vedantu Indore Rs67k | K10: Case brief used Rs60k | L10: 0 | M10: =IF(AND(G10>=MIN(D10,F10),G10<=MAX(D10,F10)),0,1)
A11: Fee_L | B11: Annual fee per student - Large | C11: Rs/yr | D11: 100000 | E11: 125000 | F11: 150000 | G11: =CHOOSE(Scenario,D11,E11,F11) | H11: Researched | I11: M | J11: R2: Udaan Patna Rs1.15-1.25L/yr (own site 2025-27); chains Rs1.1-1.4L (Motion/Allen/Vedantu) | L11: 0 | M11: =IF(AND(G11>=MIN(D11,F11),G11<=MAX(D11,F11)),0,1)
A12: OnboardMult_S | B12: Onboarding cost multiplier - Small | C12: x | D12: 0.8 | E12: 0.8 | F12: 0.8 | G12: =CHOOSE(Scenario,D12,E12,F12) | H12: Assumption | I12: L | J12: Fewer batches to migrate | L12: 0 | M12: =IF(AND(G12>=MIN(D12,F12),G12<=MAX(D12,F12)),0,1)
A13: OnboardMult_M | B13: Onboarding cost multiplier - Mid | C13: x | D13: 1 | E13: 1 | F13: 1 | G13: =CHOOSE(Scenario,D13,E13,F13) | H13: Structural | I13: H | J13: Reference segment | L13: 0 | M13: =IF(AND(G13>=MIN(D13,F13),G13<=MAX(D13,F13)),0,1)
A14: OnboardMult_L | B14: Onboarding cost multiplier - Large | C14: x | D14: 1.6 | E14: 1.6 | F14: 1.6 | G14: =CHOOSE(Scenario,D14,E14,F14) | H14: Assumption | I14: L | J14: More batches and staff to train | L14: 0 | M14: =IF(AND(G14>=MIN(D14,F14),G14<=MAX(D14,F14)),0,1)
A15: Institute
A16: DropoutRate | B16: Mid-session dropout/default rate | C16: % of students/yr | D16: 0.06 | E16: 0.1 | F16: 0.18 | G16: =CHOOSE(Scenario,D16,E16,F16) | H16: Researched | I16: L | J16: R3: Coaching Federation of India 'at least 10 per cent of students in every batch' (ThePrint 31-Jul-2025); YourStory May-2026 ~20% offline (unattributed); analogue UDISE+ Cl.9-10 11.5% | K16: Higher = more value to protect (Bull); case brief 8-15% | L16: =IF(OR(G16<0,G16>1),1,0) | M16: =IF(AND(G16>=MIN(D16,F16),G16<=MAX(D16,F16)),0,1)
A17: UpfrontShare | B17: Share of students paying full fee upfront | C17: % | D17: 0.4 | E17: 0.25 | F17: 0.15 | G17: =CHOOSE(Scenario,D17,E17,F17) | H17: Assumption | I17: L | J17: R2: not found. Instalments are the norm (Allen 2; PW 3; Aakash several; Rajasthan Act s.6(2)(d) >=4 option) | K17: TECH_PLAN's 35% had no source | L17: =IF(OR(G17<0,G17>1),1,0) | M17: =IF(AND(G17>=MIN(D17,F17),G17<=MAX(D17,F17)),0,1)
A18: NInstalments | B18: Instalments per year for non-upfront payers | C18: count | D18: 2 | E18: 3 | F18: 4 | G18: =CHOOSE(Scenario,D18,E18,F18) | H18: Researched | I18: M | J18: R2: Allen 2 (2nd within 45 days); PW 3; Rajasthan Act 16/2025 s.6(2)(d) min. 4 equal | K18: Fewer instalments = cash collected early = less at risk | L18: 0 | M18: =IF(AND(G18>=MIN(D18,F18),G18<=MAX(D18,F18)),0,1)
A19: RefundEnforced | B19: Share of upfront leavers actually refunded pro-rata | C19: % | D19: 0.1 | E19: 0.3 | F19: 0.6 | G19: =CHOOSE(Scenario,D19,E19,F19) | H19: Assumption | I19: L | J19: R2: MoE Guidelines 2024 cl.8(iv) and Rajasthan s.13(4) require pro-rata refund within 10 days; MoE is advisory and Allen/Aakash/PW practice is cut-off or no refund | K19: Refunded upfront leavers = fee at risk | L19: =IF(OR(G19<0,G19>1),1,0) | M19: =IF(AND(G19>=MIN(D19,F19),G19<=MAX(D19,F19)),0,1)
A20: CourseMonths | B20: Course length | C20: months | D20: 10 | E20: 10 | F20: 10 | G20: =CHOOSE(Scenario,D20,E20,F20) | H20: Guide | I20: H | J20: Case brief ~10 months | L20: 0 | M20: =IF(AND(G20>=MIN(D20,F20),G20<=MAX(D20,F20)),0,1)
A21: BlindMonths | B21: Months before the model can flag (no test data yet) | C21: months | D21: 2 | E21: 1 | F21: 0 | G21: =CHOOSE(Scenario,D21,E21,F21) | H21: Assumption | I21: M | J21: Model needs >=1-2 tests; R2: refund windows weeks 1-4 mean early exits are fast | K21: Dropouts in these months cannot be caught | L21: 0 | M21: =IF(AND(G21>=MIN(D21,F21),G21<=MAX(D21,F21)),0,1)
A22: Preventable | B22: Share of dropouts that are preventable (check only) | C22: % | D22: 0.3 | E22: 0.45 | F22: 0.6 | G22: =CHOOSE(Scenario,D22,E22,F22) | H22: Assumption | I22: L | J22: R3: reasons listed without shares (interest; family; health; dissatisfaction - ThePrint/CFI) | K22: Upper bound for the RCT effect | L22: =IF(OR(G22<0,G22>1),1,0) | M22: =IF(AND(G22>=MIN(D22,F22),G22<=MAX(D22,F22)),0,1)
A23: MinorShare | B23: Share of students under 18 | C23: % | D23: 0.85 | E23: 0.75 | F23: 0.6 | G23: =CHOOSE(Scenario,D23,E23,F23) | H23: Assumption | I23: M | J23: JEE/NEET Class 11-12 are 16-17; droppers 18+ | K23: DPDP s.9(3): minors get academic-support model + rules only | L23: =IF(OR(G23<0,G23>1),1,0) | M23: =IF(AND(G23>=MIN(D23,F23),G23<=MAX(D23,F23)),0,1)
A24: Recall_Minor | B24: Model recall on minors (academic-support + rules) | C24: % | D24: 0.4 | E24: 0.55 | F24: 0.7 | G24: =CHOOSE(Scenario,D24,E24,F24) | H24: Assumption | I24: L | J24: TECH_PLAN NB04 rules-only vs ML; replace with metrics.json | K24: At mentor-capacity threshold | L24: =IF(OR(G24<0,G24>1),1,0) | M24: =IF(AND(G24>=MIN(D24,F24),G24<=MAX(D24,F24)),0,1)
A25: Recall_Adult | B25: Model recall on 18+ (full ML) | C25: % | D25: 0.5 | E25: 0.65 | F25: 0.8 | G25: =CHOOSE(Scenario,D25,E25,F25) | H25: Public | I25: M | J25: OULAD withdrawal AUC 0.727-0.794 (TECH_PLAN s.24); replace with metrics.json | K25: At mentor-capacity threshold | L25: =IF(OR(G25<0,G25>1),1,0) | M25: =IF(AND(G25>=MIN(D25,F25),G25<=MAX(D25,F25)),0,1)
A26: Precision | B26: Precision of at-risk flag | C26: % | D26: 0.25 | E26: 0.35 | F26: 0.5 | G26: =CHOOSE(Scenario,D26,E26,F26) | H26: Assumption | I26: L | J26: Replace with metrics.json | K26: Drives wasted mentor time | L26: =IF(OR(G26<0,G26>1),1,0) | M26: =IF(AND(G26>=MIN(D26,F26),G26<=MAX(D26,F26)),0,1)
A27: ActionRate | B27: Share of flags the institute assigns to outreach | C27: % | D27: 0.7 | E27: 0.9 | F27: 1 | G27: =CHOOSE(Scenario,D27,E27,F27) | H27: Assumption | I27: L | J27: Mentor capacity; the RCT effect below is already intention-to-treat | K27: Primary research needed | L27: =IF(OR(G27<0,G27>1),1,0) | M27: =IF(AND(G27>=MIN(D27,F27),G27<=MAX(D27,F27)),0,1)
A28: InterventionSuccess | B28: Dropout reduction among flagged students given outreach (RCT) | C28: relative % | D28: 0.05 | E28: 0.15 | F28: 0.3 | G28: =CHOOSE(Scenario,D28,E28,F28) | H28: Researched | I28: M | J28: R4: mean 15.8% / median 12.5% over 8 RCTs - OU outreach RCT 2020 -19%/-35%; Room to Read India -30%; Bergman parent texts; MAAPS/Samata/Oreopoulos nulls (research/R4_R5) | K28: Borrowed from other settings - not our measured effect | L28: =IF(OR(G28<0,G28>1),1,0) | M28: =IF(AND(G28>=MIN(D28,F28),G28<=MAX(D28,F28)),0,1)
A29: AdmissionUplift | B29: Admissions uplift next session from results/parent trust | C29: % of students | D29: 0 | E29: 0.01 | F29: 0.03 | G29: =CHOOSE(Scenario,D29,E29,F29) | H29: Assumption | I29: L | J29: No evidence - Bear = 0 | L29: =IF(OR(G29<0,G29>1),1,0) | M29: =IF(AND(G29>=MIN(D29,F29),G29<=MAX(D29,F29)),0,1)
A30: MarginExtraAdmission | B30: Institute margin on one extra admission | C30: % | D30: 0.4 | E30: 0.6 | F30: 0.8 | G30: =CHOOSE(Scenario,D30,E30,F30) | H30: Assumption | I30: L | J30: Marginal seat in an existing batch | L30: =IF(OR(G30<0,G30>1),1,0) | M30: =IF(AND(G30>=MIN(D30,F30),G30<=MAX(D30,F30)),0,1)
A31: StaffHoursSaved | B31: Staff hours saved per month | C31: hours/month | D31: 10 | E31: 25 | F31: 50 | G31: =CHOOSE(Scenario,D31,E31,F31) | H31: Guide | I31: L | J31: Case brief value lever; primary research needed | L31: 0 | M31: =IF(AND(G31>=MIN(D31,F31),G31<=MAX(D31,F31)),0,1)
A32: StaffHourCost | B32: Cost of one admin staff hour | C32: Rs/hour | D32: 75 | E32: 100 | F32: 150 | G32: =CHOOSE(Scenario,D32,E32,F32) | H32: Researched | I32: M | J32: R5: Tier-2 executive pay Rs18-25k/month (Payscale/Indeed Patna) / ~200 h | L32: 0 | M32: =IF(AND(G32>=MIN(D32,F32),G32<=MAX(D32,F32)),0,1)
A33: InterventionMinutes | B33: Mentor minutes per intervention | C33: minutes | D33: 45 | E33: 30 | F33: 20 | G33: =CHOOSE(Scenario,D33,E33,F33) | H33: Assumption | I33: L | J33: Call + meeting with parent | L33: 0 | M33: =IF(AND(G33>=MIN(D33,F33),G33<=MAX(D33,F33)),0,1)
A34: MentorHourCost | B34: Cost of one mentor hour | C34: Rs/hour | D34: 250 | E34: 200 | F34: 150 | G34: =CHOOSE(Scenario,D34,E34,F34) | H34: Assumption | I34: M | J34: Teacher pay ~Rs30-50k/month / ~200 h | L34: 0 | M34: =IF(AND(G34>=MIN(D34,F34),G34<=MAX(D34,F34)),0,1)
A35: GST | B35: GST on SaaS | C35: % | D35: 0.18 | E35: 0.18 | F35: 0.18 | G35: =CHOOSE(Scenario,D35,E35,F35) | H35: Researched | I35: M | J35: R6: 18% (heading 9983 residual entry; Notif. 11/2017-CTR as amended by 15/2025-CTR) | K35: SAC code 9983 vs 9984 unconfirmed - ask a CA | L35: =IF(OR(G35<0,G35>1),1,0) | M35: =IF(AND(G35>=MIN(D35,F35),G35<=MAX(D35,F35)),0,1)
A36: ITCShare | B36: Share of institutes that reclaim our GST as input credit | C36: % | D36: 0.3 | E36: 0.6 | F36: 0.9 | G36: =CHOOSE(Scenario,D36,E36,F36) | H36: Assumption | I36: L | J36: R6: coaching is taxable at 18%; registration mandatory above Rs20L turnover; CGST s.16(1) gives ITC to registered persons. A 180-student institute turns over ~Rs1 Cr, so legally registered - but cash/informal practice in Tier-3 | K36: Was 'all unregistered' in the naive view | L36: =IF(OR(G36<0,G36>1),1,0) | M36: =IF(AND(G36>=MIN(D36,F36),G36<=MAX(D36,F36)),0,1)
A37: Pricing
A38: ListPrice | B38: List price per active student per month | C38: Rs/student/month | D38: 20 | E38: 30 | F38: 40 | G38: =CHOOSE(Scenario,D38,E38,F38) | H38: Assumption | I38: L | J38: R1: ERP/LMS anchors Rs4-21/student/month at 400 students (Classplus/Fedena/Graphy); no competitor bundles OMR + topic analytics + Hindi WhatsApp | K38: Decision lever - test in interviews (Van Westendorp) | L38: 0 | M38: =IF(AND(G38>=MIN(D38,F38),G38<=MAX(D38,F38)),0,1)
A39: CompetitorAnchor | B39: What institutes already pay for an ERP/LMS | C39: Rs/student/month | D39: 4.17 | E39: 10.42 | F39: 20.83 | G39: =CHOOSE(Scenario,D39,E39,F39) | H39: Researched | I39: M | J39: R1: Classplus Starter Rs19999/yr (Capterra); Fedena Standard / Graphy Grow Rs50k/yr; Fedena Ultimate Rs1L/yr - all at 400 students | K39: Reference only - not used in revenue | L39: 0 | M39: =IF(AND(G39>=MIN(D39,F39),G39<=MAX(D39,F39)),0,1)
A40: CompetitorAnchorHigh | B40: Highest priced ERP/LMS anchor found | C40: Rs/student/month | D40: 20.83 | E40: 20.83 | F40: 20.83 | G40: =CHOOSE(Scenario,D40,E40,F40) | H40: Researched | I40: M | J40: R1: Fedena Ultimate / Graphy Rise Rs1L/yr at 400 students | K40: Used in a warning check | L40: 0 | M40: =IF(AND(G40>=MIN(D40,F40),G40<=MAX(D40,F40)),0,1)
A41: MinFee | B41: Minimum monthly fee per institute | C41: Rs/month | D41: 2000 | E41: 3000 | F41: 4000 | G41: =CHOOSE(Scenario,D41,E41,F41) | H41: Assumption | I41: L | J41: FINANCE_PLAN s.3.2 | L41: 0 | M41: =IF(AND(G41>=MIN(D41,F41),G41<=MAX(D41,F41)),0,1)
...

Sheet Seasonality
A1: Seasonality, dropout timing and the 60-month timeline
A2: Session month 1 = April. Blue cells are inputs (currently assumptions, see Source).
A3: A. Active-student index and renewal (churn) months
A4: No. | B4: Month | C4: Active-student index | D4: Renewal month (1/0) | E4: Source
A5: 1 | B5: Apr | C5: 0.85 | D5: 1 | E5: Assumption (L): new session starts; admissions still coming in | flag: Assumption: renewal decision for the new session
A6: 2 | B6: May | C6: 0.95 | D6: 1 | E6: Assumption (L) | flag: Assumption
A7: 3 | B7: Jun | C7: 1 | D7: 0 | E7: Assumption (L)
A8: 4 | B8: Jul | C8: 1 | D8: 0 | E8: Assumption (L)
A9: 5 | B9: Aug | C9: 1 | D9: 0 | E9: Assumption (L)
A10: 6 | B10: Sep | C10: 1 | D10: 0 | E10: Assumption (L)
A11: 7 | B11: Oct | C11: 0.98 | D11: 0 | E11: Assumption (L): dropouts start reducing roster
A12: 8 | B12: Nov | C12: 0.96 | D12: 0 | E12: Assumption (L)
A13: 9 | B13: Dec | C13: 0.93 | D13: 0 | E13: Assumption (L)
A14: 10 | B14: Jan | C14: 0.85 | D14: 0 | E14: Assumption (L): JEE Main Jan; 12th students thin out
A15: 11 | B15: Feb | C15: 0.6 | D15: 0 | E15: Assumption (L): board exams
A16: 12 | B16: Mar | C16: 0.45 | D16: 1 | E16: Assumption (L): boards end; session over for 12th | flag: Assumption: post-exam churn window
B18: Renewal months per year | C18: =SUM(Season_Flag)
A20: B. When in the course students drop out
A21: Course month | C21: Share of dropouts | D21: Share of course left | E21: Source
A22: 1 | B22: Course month 1 | C22: 0.15 | D22: =MAX(0,(CourseMonths-A22)/CourseMonths) | E22: Assumption (L): R3 found no monthly data; front-loaded shape from refund windows (weeks 1-4) and case exits at months 2-4 (ThePrint 2025)
A23: 2 | B23: Course month 2 | C23: 0.15 | D23: =MAX(0,(CourseMonths-A23)/CourseMonths) | E23: Assumption (L): R3 base curve
A24: 3 | B24: Course month 3 | C24: 0.14 | D24: =MAX(0,(CourseMonths-A24)/CourseMonths) | E24: Assumption (L): R3 base curve
A25: 4 | B25: Course month 4 | C25: 0.12 | D25: =MAX(0,(CourseMonths-A25)/CourseMonths) | E25: Assumption (L): R3 base curve
A26: 5 | B26: Course month 5 | C26: 0.1 | D26: =MAX(0,(CourseMonths-A26)/CourseMonths) | E26: Assumption (L): R3 base curve
A27: 6 | B27: Course month 6 | C27: 0.09 | D27: =MAX(0,(CourseMonths-A27)/CourseMonths) | E27: Assumption (L): R3 base curve
A28: 7 | B28: Course month 7 | C28: 0.08 | D28: =MAX(0,(CourseMonths-A28)/CourseMonths) | E28: Assumption (L): R3 base curve
A29: 8 | B29: Course month 8 | C29: 0.07 | D29: =MAX(0,(CourseMonths-A29)/CourseMonths) | E29: Assumption (L): R3 base curve
A30: 9 | B30: Course month 9 | C30: 0.06 | D30: =MAX(0,(CourseMonths-A30)/CourseMonths) | E30: Assumption (L): R3 base curve
A31: 10 | B31: Course month 10 | C31: 0.04 | D31: =MAX(0,(CourseMonths-A31)/CourseMonths) | E31: Assumption (L): R3 base curve
B32: Total (must be 100%) | C32: =SUM(DropTiming)
A34: C. Timeline for LTV: paid month t → calendar month, student index, renewal flag, discount factor
A36: t (paid month) | B36: Calendar month # | C36: Active-student index | D36: Renewal flag | E36: Discount factor
A37: 1 | B37: =MOD(StartMonth+A37-2,12)+1 | C37: =INDEX(Season_Idx,B37) | D37: =INDEX(Season_Flag,B37) | E37: =1/(1+DiscountRate)^(A37/12)
A38: 2 | B38: =MOD(StartMonth+A38-2,12)+1 | C38: =INDEX(Season_Idx,B38) | D38: =INDEX(Season_Flag,B38) | E38: =1/(1+DiscountRate)^(A38/12)
A39: 3 | B39: =MOD(StartMonth+A39-2,12)+1 | C39: =INDEX(Season_Idx,B39) | D39: =INDEX(Season_Flag,B39) | E39: =1/(1+DiscountRate)^(A39/12)
A40: 4 | B40: =MOD(StartMonth+A40-2,12)+1 | C40: =INDEX(Season_Idx,B40) | D40: =INDEX(Season_Flag,B40) | E40: =1/(1+DiscountRate)^(A40/12)
A41: 5 | B41: =MOD(StartMonth+A41-2,12)+1 | C41: =INDEX(Season_Idx,B41) | D41: =INDEX(Season_Flag,B41) | E41: =1/(1+DiscountRate)^(A41/12)
A42: 6 | B42: =MOD(StartMonth+A42-2,12)+1 | C42: =INDEX(Season_Idx,B42) | D42: =INDEX(Season_Flag,B42) | E42: =1/(1+DiscountRate)^(A42/12)
A43: 7 | B43: =MOD(StartMonth+A43-2,12)+1 | C43: =INDEX(Season_Idx,B43) | D43: =INDEX(Season_Flag,B43) | E43: =1/(1+DiscountRate)^(A43/12)
A44: 8 | B44: =MOD(StartMonth+A44-2,12)+1 | C44: =INDEX(Season_Idx,B44) | D44: =INDEX(Season_Flag,B44) | E44: =1/(1+DiscountRate)^(A44/12)
...

Sheet Pricing
A1: Pricing — list price, discounts, realised price
A2: Green = linked input · black = formula · green fill = output used elsewhere
B4: Item | C4: Unit | D4: LIVE
B5: Inputs (from Assumptions)
B6: List price per active student per month | C6: Rs/student/month | D6: =ListPrice
B7: Minimum monthly fee per institute | C7: Rs/month | D7: =MinFee
B8: Average negotiated discount off list | C8: % | D8: =NegotiationDisc
B9: Share of institutes choosing annual prepay | C9: % | D9: =PrepayUptake
B10: Annual prepay discount | C10: % | D10: =PrepayDisc
B11: GST on SaaS | C11: % | D11: =GST
B12: Realised price
B13: Effective discount = negotiation + prepay uptake × prepay discount | C13: % | D13: =D8+D9*D10
B14: Realised price per student-month (ex-GST) | C14: ₹/student/month | D14: =D6*(1-D13)
B15: Price the owner feels (incl. GST) | C15: ₹/student/month | D15: =D14*(1+D11)
B16: What institutes already pay for an ERP/LMS | C16: Rs/student/month | D16: =CompetitorAnchor
B17: Our realised price ÷ what institutes already pay for an ERP/LMS | C17: x | D17: =IF(D16>0,D14/D16,0)
A20: Packaging (for the deck; Pro price is the model's list price)
A21: Tier | B21: Contents | C21: Price | D21: Role
A22: Starter | B22: CSV / OMR upload, test-level reports, 1 batch | C22: 0 | D22: Free — lead generation, data on-ramp
A23: Pro (core) | B23: Topic heatmap, at-risk list with reasons, template parent reports | C23: =ListPrice | D23: Core paid plan, ₹/active student/month, min fee applies
A24: Premium (AI) | B24: GenAI Hindi/English parent reports on WhatsApp, percentile band, study plans | C24: Pro + add-on | D24: Upsell — NOT in base revenue until priced by research
A25: Annual plan | B25: Pro billed yearly upfront | C25: =ListPrice*(1-PrepayDisc) | D25: Cash up front, lower churn at renewal

Sheet COGS_Build
A1: COGS build-up — cost to serve one student (must match TECH_PLAN §16 / NB09)
A2: Mid-segment size used for the all-in figure. Tech plan target band: ₹3–10 per student-month.
B4: Item | C4: Unit | D4: LIVE
B5: Inputs (from Assumptions)
B6: AI parent reports per student per month | C6: reports | D6: =ReportsPerStudentMonth
B7: LLM input tokens per report | C7: tokens | D7: =TokensInPerReport
B8: LLM output tokens per report | C8: tokens | D8: =TokensOutPerReport
B9: LLM input price (hosted) | C9: Rs per 1M tokens | D9: =LLMPriceIn
B10: LLM output price (hosted) | C10: Rs per 1M tokens | D10: =LLMPriceOut
B11: WhatsApp utility messages per student per month | C11: messages | D11: =WAMsgsPerStudentMonth
B12: WhatsApp utility message price (India) | C12: Rs/message | D12: =WAPricePerMsg
B13: Compute + storage + backups per student | C13: Rs/student/month | D13: =ComputePerStudentMonth
B14: Consent OTP + verification per student | C14: Rs/student/yr | D14: =ConsentCostPerStudentYear
B15: App server + managed Postgres + backups per stack | C15: Rs/month | D15: =ServerCostMonth
B16: WhatsApp BSP platform fee per stack | C16: Rs/month | D16: =BSPFeeMonth
B17: Institutes sharing one server stack | C17: institutes | D17: =InstPerStack
B18: DPDP compliance cost per institute | C18: Rs/month | D18: =CompliancePerInstMonth
B19: Students per institute | C19: students | D19: =Students_M
B20: Variable cost per active student per month
B21: LLM (AI parent reports, hosted model) | C21: ₹/student/month | D21: =D6*(D7*D9+D8*D10)/1000000
B22: WhatsApp utility messages | C22: ₹/student/month | D22: =D11*D12
B23: Compute + storage + backups | C23: ₹/student/month | D23: =D13
B24: Consent OTP / verification (annual ÷ 12) | C24: ₹/student/month | D24: =D14/12
B25: Total variable COGS per student-month | C25: ₹/student/month | D25: =SUM(D21:D24)
B26: Fixed cost per institute per month
B27: Hosting share = (server + DB + WhatsApp BSP fee) ÷ institutes per stack | C27: ₹/institute/month | D27: =(D15+D16)/D17
B28: Hosting share + DPDP compliance | C28: ₹/institute/month | D28: =D27+D18
B29: All-in COGS per student-month at this size | C29: ₹/student/month | D29: =D25+D28/D19

Sheet Institute_ROI
A1: Institute ROI — does it pay for the owner? (per segment, live scenario)
A2: Same price and same dropout funnel as Unit_Econ. Green fill = key outputs.
B4: Line | C4: Unit | D4: Small (<250) | E4: Mid (250-800) | F4: Large (>800)
B5: Inputs (from Assumptions / Pricing)
B6: Students per institute | C6: students | D6: =Students_S | E6: =Students_M | F6: =Students_L
B7: Annual fee per student | C7: Rs/yr | D7: =Fee_S | E7: =Fee_M | F7: =Fee_L
B8: Mid-session dropout/default rate | C8: % of students/yr | D8: =DropoutRate | E8: =DropoutRate | F8: =DropoutRate
B9: Share of students paying full fee upfront | C9: % | D9: =UpfrontShare | E9: =UpfrontShare | F9: =UpfrontShare
B10: Instalments per year for non-upfront payers | C10: count | D10: =NInstalments | E10: =NInstalments | F10: =NInstalments
B11: Share of upfront leavers actually refunded pro-rata | C11: % | D11: =RefundEnforced | E11: =RefundEnforced | F11: =RefundEnforced
B12: Months before the model can flag (no test data yet) | C12: months | D12: =BlindMonths | E12: =BlindMonths | F12: =BlindMonths
B13: Share of students under 18 | C13: % | D13: =MinorShare | E13: =MinorShare | F13: =MinorShare
B14: Model recall on minors (academic-support + rules) | C14: % | D14: =Recall_Minor | E14: =Recall_Minor | F14: =Recall_Minor
B15: Model recall on 18+ (full ML) | C15: % | D15: =Recall_Adult | E15: =Recall_Adult | F15: =Recall_Adult
B16: Precision of at-risk flag | C16: % | D16: =Precision | E16: =Precision | F16: =Precision
B17: Share of flags the institute assigns to outreach | C17: % | D17: =ActionRate | E17: =ActionRate | F17: =ActionRate
B18: Dropout reduction among flagged students given outreach (RCT) | C18: relative % | D18: =InterventionSuccess | E18: =InterventionSuccess | F18: =InterventionSuccess
B19: Admissions uplift next session from results/parent trust | C19: % of students | D19: =AdmissionUplift | E19: =AdmissionUplift | F19: =AdmissionUplift
B20: Institute margin on one extra admission | C20: % | D20: =MarginExtraAdmission | E20: =MarginExtraAdmission | F20: =MarginExtraAdmission
B21: Staff hours saved per month | C21: hours/month | D21: =StaffHoursSaved | E21: =StaffHoursSaved | F21: =StaffHoursSaved
B22: Cost of one admin staff hour | C22: Rs/hour | D22: =StaffHourCost | E22: =StaffHourCost | F22: =StaffHourCost
B23: Mentor minutes per intervention | C23: minutes | D23: =InterventionMinutes | E23: =InterventionMinutes | F23: =InterventionMinutes
B24: Cost of one mentor hour | C24: Rs/hour | D24: =MentorHourCost | E24: =MentorHourCost | F24: =MentorHourCost
B25: List price per active student per month | C25: Rs/student/month | D25: =ListPrice | E25: =ListPrice | F25: =ListPrice
B26: Minimum monthly fee per institute | C26: Rs/month | D26: =MinFee | E26: =MinFee | F26: =MinFee
B27: GST on SaaS | C27: % | D27: =GST | E27: =GST | F27: =GST
B28: Share of institutes that reclaim our GST as input credit | C28: % | D28: =ITCShare | E28: =ITCShare | F28: =ITCShare
B29: Effective discount (Pricing) | C29: % | D29: =EffDisc | E29: =EffDisc | F29: =EffDisc
B30: 1. What a dropout actually costs (unpaid instalments + refunds to full payers)
B31: Dropouts per year | C31: students/yr | D31: =D6*D8 | E31: =E6*E8 | F31: =F6*F8
B32: Avg fee lost per dropout (timing curve × unpaid instalments / pro-rata refund) | C32: ₹/dropout | D32: =SUMPRODUCT(DropTiming,D7*((1-D9)*(1-(INT((DropMonth-1)*D10/CourseMonths)+1)/D10)+D9*D11*DropRemain)) | E32: =SUMPRODUCT(DropTiming,E7*((1-E9)*(1-(INT((DropMonth-1)*E10/CourseMonths)+1)/E10)+E9*E11*DropRemain)) | F32: =SUMPRODUCT(DropTiming,F7*((1-F9)*(1-(INT((DropMonth-1)*F10/CourseMonths)+1)/F10)+F9*F11*DropRemain))
B33: Fee lost to dropouts per year (no platform) | C33: ₹/yr | D33: =D31*D32 | E33: =E31*E32 | F33: =F31*F32
B34: 2. Prevention funnel (replaces the guide's flat 25%)
B35: Blended recall (minors: academic model + rules; 18+: full ML) | C35: % | D35: =D13*D14+(1-D13)*D15 | E35: =E13*E14+(1-E13)*E15 | F35: =F13*F14+(1-F13)*F15
B36: Share of dropouts after the 'blind' months (enough test data to flag) | C36: % | D36: =SUMPRODUCT(DropTiming*(DropMonth>D12)) | E36: =SUMPRODUCT(DropTiming*(DropMonth>E12)) | F36: =SUMPRODUCT(DropTiming*(DropMonth>F12))
B37: Effective dropout reduction = recall × action × RCT effect × catchable | C37: % | D37: =D35*D17*D18*D36 | E37: =E35*E17*E18*E36 | F37: =F35*F17*F18*F36
B38: Dropouts prevented per year | C38: students/yr | D38: =D31*D37 | E38: =E31*E37 | F38: =F31*F37
B39: Fee saved per prevented dropout (catchable months only) | C39: ₹/student | D39: =IF(D36>0,SUMPRODUCT(DropTiming*(DropMonth>D12)*D7*((1-D9)*(1-(INT((DropMonth-1)*D10/CourseMonths)+1)/D10)+D9*D11*DropRemain))/D36,0) | E39: =IF(E36>0,SUMPRODUCT(DropTiming*(DropMonth>E12)*E7*((1-E9)*(1-(INT((DropMonth-1)*E10/CourseMonths)+1)/E10)+E9*E11*DropRemain))/E36,0) | F39: =IF(F36>0,SUMPRODUCT(DropTiming*(DropMonth>F12)*F7*((1-F9)*(1-(INT((DropMonth-1)*F10/CourseMonths)+1)/F10)+F9*F11*DropRemain))/F36,0)
B40: 3. Value to the institute (₹/yr)
B41: Fees retained | C41: ₹/yr | D41: =D38*D39 | E41: =E38*E39 | F41: =F38*F39
...

Sheet Unit_Econ
A1: Unit economics per institute (live scenario)
A2: LTV uses a seasonal survival curve (monthly churn + renewal spike), discounted, capped at 60 months. Payback = 61 means 'not within 60 months'.
B4: Line | C4: Unit | D4: Small (<250) | E4: Mid (250-800) | F4: Large (>800) | H4: Guide's naive unit economics | I4: Value
B5: Inputs (from Assumptions / Pricing / COGS_Build) | H5: Revenue per institute per month | I5: =G_Students*G_Price
B6: Students per institute | C6: students | D6: =Students_S | E6: =Students_M | F6: =Students_L | H6: Contribution per month | I6: =G_Students*G_Price-G_Students*G_Infra-G_Support
B7: List price per active student per month | C7: Rs/student/month | D7: =ListPrice | E7: =ListPrice | F7: =ListPrice | H7: CAC + onboarding | I7: =G_CAC+G_Onboard
B8: Minimum monthly fee per institute | C8: Rs/month | D8: =MinFee | E8: =MinFee | F8: =MinFee | H8: Payback (months) | I8: =(G_CAC+G_Onboard)/(G_Students*G_Price-G_Students*G_Infra-G_Support)
B9: Bad debt / uncollected billing | C9: % | D9: =BadDebt | E9: =BadDebt | F9: =BadDebt | H9: LTV = contribution ÷ churn | I9: =(G_Students*G_Price-G_Students*G_Infra-G_Support)/G_Churn
B10: Payment collection cost (blended) | C10: % of revenue | D10: =GatewayFee | E10: =GatewayFee | F10: =GatewayFee | H10: LTV ÷ (CAC + onboarding) | I10: =((G_Students*G_Price-G_Students*G_Infra-G_Support)/G_Churn)/(G_CAC+G_Onboard)
B11: Monthly logo churn for monthly payers | C11: %/month | D11: =ChurnInSeason | E11: =ChurnInSeason | F11: =ChurnInSeason
B12: Share of institutes choosing annual prepay | C12: % | D12: =PrepayUptake | E12: =PrepayUptake | F12: =PrepayUptake
B13: Non-renewal at session end (annual) | C13: % of logos | D13: =RenewalSpike | E13: =RenewalSpike | F13: =RenewalSpike | H13: Break-even scale (fixed team cost ÷ Mid contribution) | I13: Value
B14: Customer-success / onboarding exec monthly CTC | C14: Rs/month | D14: =CSM_CTC | E14: =CSM_CTC | F14: =CSM_CTC | H14: Fixed team + tools cost per month | I14: =Founders*FounderStipend+Engineers*EngineerCTC+ToolsOpex
B15: Institutes per CSM | C15: institutes | D15: =InstPerCSM | E15: =InstPerCSM | F15: =InstPerCSM | H15: Mid-institute avg monthly contribution | I15: =E34
B16: Field sales rep monthly CTC (incl. fuel) | C16: Rs/month | D16: =RepCTC | E16: =RepCTC | F16: =RepCTC | H16: Institutes needed to cover fixed cost | I16: =IF(I15>0,I14/I15,0)
B17: Rep intercity travel + demo material per month | C17: Rs/month | D17: =RepTravel | E17: =RepTravel | F17: =RepTravel | H17: …equivalent active students | I17: =I16*Students_M
B18: Pilots started per rep per month (yearly avg) | C18: pilots | D18: =PilotsPerRepMonth | E18: =PilotsPerRepMonth | F18: =PilotsPerRepMonth | H18: Paid institutes one rep adds per month | I18: =PilotsPerRepMonth*PilotConv
B19: Pilot-to-paid conversion | C19: % | D19: =PilotConv | E19: =PilotConv | F19: =PilotConv
B20: Free pilot length | C20: months | D20: =PilotMonths | E20: =PilotMonths | F20: =PilotMonths | H20: Full hiring plan, cohorts, cash and funding need: Round 2 sheets.
B21: Retro-pilot setup (import last year's Excel; show who left) | C21: Rs per pilot | D21: =PilotSetupCost | E21: =PilotSetupCost | F21: =PilotSetupCost
B22: Onboarding cost per institute (mid) | C22: Rs | D22: =OnboardBase | E22: =OnboardBase | F22: =OnboardBase
B23: Onboarding cost multiplier | C23: x | D23: =OnboardMult_S | E23: =OnboardMult_M | F23: =OnboardMult_L
B24: Marketing spend per paid institute | C24: Rs | D24: =MarketingPerPaid | E24: =MarketingPerPaid | F24: =MarketingPerPaid
B25: Effective discount (Pricing) | C25: % | D25: =EffDisc | E25: =EffDisc | F25: =EffDisc
B26: Variable COGS per student-month (COGS_Build) | C26: ₹/student/month | D26: =COGS_PerStudent | E26: =COGS_PerStudent | F26: =COGS_PerStudent
B27: Fixed COGS per institute-month (COGS_Build) | C27: ₹/month | D27: =COGS_FixedInst | E27: =COGS_FixedInst | F27: =COGS_FixedInst
B28: 1. Year-1 economics per institute (before churn)
B29: Collected revenue, first 12 paid months (ex-GST, after bad debt) | C29: ₹/yr | D29: =SUM(D52:D63) | E29: =SUM(E52:E63) | F29: =SUM(F52:F63)
B30: Average monthly revenue | C30: ₹/month | D30: =D29/12 | E30: =E29/12 | F30: =F29/12
B31: COGS, first 12 months (students × seasonality × COGS + fixed + gateway) | C31: ₹/yr | D31: =D6*D26*SUM(Seasonality!$C$37:$C$48)+12*D27+D10*D29 | E31: =E6*E26*SUM(Seasonality!$C$37:$C$48)+12*E27+E10*E29 | F31: =F6*F26*SUM(Seasonality!$C$37:$C$48)+12*F27+F10*F29
B32: Gross margin | C32: % | D32: =IF(D29>0,(D29-D31)/D29,0) | E32: =IF(E29>0,(E29-E31)/E29,0) | F32: =IF(F29>0,(F29-F31)/F29,0)
B33: Customer-success cost per institute | C33: ₹/month | D33: =D14/D15 | E33: =E14/E15 | F33: =F14/F15
B34: Average monthly contribution (after COGS + support) | C34: ₹/month | D34: =SUM(D112:D123)/12 | E34: =SUM(E112:E123)/12 | F34: =SUM(F112:F123)/12
B35: Contribution margin | C35: % | D35: =IF(D30>0,D34/D30,0) | E35: =IF(E30>0,E34/E30,0) | F35: =IF(F30>0,F34/F30,0)
B36: 2. Cost to acquire one paying institute
B37: Sales cost per pilot started (rep CTC + travel ÷ pilots) | C37: ₹ | D37: =(D16+D17)/D18 | E37: =(E16+E17)/E18 | F37: =(F16+F17)/F18
B38: Onboarding cost (data migration + training) | C38: ₹ | D38: =D22*D23 | E38: =E22*E23 | F38: =F22*F23
B39: Cost of serving the free pilot | C39: ₹ | D39: =D20*(D6*D26+D27) | E39: =E20*(E6*E26+E27) | F39: =F20*(F6*F26+F27)
B40: CAC: sales + marketing per paid institute (failed pilots included) | C40: ₹ | D40: =D37/D19+D24 | E40: =E37/E19+E24 | F40: =F37/F19+F24
B41: Fully loaded acquisition cost = (sales + pilot setup + pilot COGS) ÷ conversion + onboarding (paid only) + marketing | C41: ₹ | D41: =(D37+D21+D39)/D19+D38+D24 | E41: =(E37+E21+E39)/E19+E38+E24 | F41: =(F37+F21+F39)/F19+F38+F24
...

Sheet Scenarios
A1: Scenarios — honest model vs the guide's naive model
A2: Bear / Base / Bull are always shown side by side, whatever the Cover selector says. Mid institute = 400 students (the guide's example).
A4: Metric (Mid institute) | B4: Unit | C4: Guide (naive) | D4: Bear | E4: Base | F4: Bull
A5: Effective dropout reduction | B5: % | C5: =Assumptions!$E$86 | D5: =Engine!$H$81 | E5: =Engine!$K$81 | F5: =Engine!$N$81
A6: Dropouts prevented per year | B6: students | C6: =Institute_ROI!$E$65 | D6: =Engine!$H$82 | E6: =Engine!$K$82 | F6: =Engine!$N$82
A7: Fee lost per dropout | B7: ₹ | C7: =G_RemainingFee | D7: =Engine!$H$77 | E7: =Engine!$K$77 | F7: =Engine!$N$77
A8: Fees retained per year | B8: ₹/yr | C8: =Institute_ROI!$E$66 | D8: =Engine!$H$84 | E8: =Engine!$K$84 | F8: =Engine!$N$84
A9: Total value to institute | B9: ₹/yr | C9: =Institute_ROI!$E$66 | D9: =Engine!$H$87 | E9: =Engine!$K$87 | F9: =Engine!$N$87
A10: Total cost to institute (fee + GST + mentor time) | B10: ₹/yr | C10: =Institute_ROI!$E$67 | D10: =Engine!$H$92 | E10: =Engine!$K$92 | F10: =Engine!$N$92
A11: Institute ROI | B11: x | C11: =Institute_ROI!$E$68 | D11: =Engine!$H$94 | E11: =Engine!$K$94 | F11: =Engine!$N$94
A12: Fees-only ROI | B12: x | C12: =Institute_ROI!$E$68 | D12: =Engine!$H$95 | E12: =Engine!$K$95 | F12: =Engine!$N$95
A13: Break-even students saved per year | B13: students | C13: =Institute_ROI!$E$69 | D13: =Engine!$H$96 | E13: =Engine!$K$96 | F13: =Engine!$N$96
A14: Avg monthly revenue per institute | B14: ₹/month | C14: =Unit_Econ!$I$5 | D14: =Engine!$H$103 | E14: =Engine!$K$103 | F14: =Engine!$N$103
A15: Avg monthly contribution | B15: ₹/month | C15: =Unit_Econ!$I$6 | D15: =Engine!$H$107 | E15: =Engine!$K$107 | F15: =Engine!$N$107
A16: Fully loaded acquisition cost | B16: ₹ | C16: =Unit_Econ!$I$7 | D16: =Engine!$H$113 | E16: =Engine!$K$113 | F16: =Engine!$N$113
A17: Annual logo retention | B17: % | C17: =(1-G_Churn)^12 | D17: =Engine!$H$116 | E17: =Engine!$K$116 | F17: =Engine!$N$116
A18: LTV | B18: ₹ | C18: =Unit_Econ!$I$9 | D18: =Engine!$H$118 | E18: =Engine!$K$118 | F18: =Engine!$N$118
A19: LTV ÷ acquisition cost | B19: x | C19: =Unit_Econ!$I$10 | D19: =Engine!$H$119 | E19: =Engine!$K$119 | F19: =Engine!$N$119
A20: Payback | B20: months | C20: =Unit_Econ!$I$8 | D20: =Engine!$H$120 | E20: =Engine!$K$120 | F20: =Engine!$N$120
A23: By segment
A24: Institute ROI | D24: Bear | E24: Base | F24: Bull
A25: Small (<250) | D25: =Engine!$G$94 | E25: =Engine!$J$94 | F25: =Engine!$M$94
A26: Mid (250-800) | D26: =Engine!$H$94 | E26: =Engine!$K$94 | F26: =Engine!$N$94
A27: Large (>800) | D27: =Engine!$I$94 | E27: =Engine!$L$94 | F27: =Engine!$O$94
A30: LTV ÷ acquisition cost | D30: Bear | E30: Base | F30: Bull
A31: Small (<250) | D31: =Engine!$G$119 | E31: =Engine!$J$119 | F31: =Engine!$M$119
A32: Mid (250-800) | D32: =Engine!$H$119 | E32: =Engine!$K$119 | F32: =Engine!$N$119
A33: Large (>800) | D33: =Engine!$I$119 | E33: =Engine!$L$119 | F33: =Engine!$O$119
A36: Payback (months) | D36: Bear | E36: Base | F36: Bull
A37: Small (<250) | D37: =Engine!$G$120 | E37: =Engine!$J$120 | F37: =Engine!$M$120
A38: Mid (250-800) | D38: =Engine!$H$120 | E38: =Engine!$K$120 | F38: =Engine!$N$120
A39: Large (>800) | D39: =Engine!$I$120 | E39: =Engine!$L$120 | F39: =Engine!$O$120

Sheet Sensitivity
A1: Sensitivity — what actually moves the answer
A2: Tornado: one input at a time moved to its Bear / Bull value, all else Base (Mid institute). Grids follow the live scenario.
A4: Input | B4: Bear value | C4: Bull value | D4: ROI @ Bear | E4: ROI @ Bull | F4: ROI swing | G4: LTV/CAC @ Bear | H4: LTV/CAC @ Bull | I4: LTV/CAC swing
A5: BASE (all inputs Base) | D5: =Engine!$K$94 | E5: =Engine!$K$94 | G5: =Engine!$K$119 | H5: =Engine!$K$119
A6: List price per active student per month | B6: =Assumptions!$D$38 | C6: =Assumptions!$F$38 | D6: =Engine!$P$94 | E6: =Engine!$Q$94 | F6: =ABS(E6-D6) | G6: =Engine!$P$119 | H6: =Engine!$Q$119 | I6: =ABS(H6-G6)
A7: Annual fee per student - Mid | B7: =Assumptions!$D$10 | C7: =Assumptions!$F$10 | D7: =Engine!$R$94 | E7: =Engine!$S$94 | F7: =ABS(E7-D7) | G7: =Engine!$R$119 | H7: =Engine!$S$119 | I7: =ABS(H7-G7)
A8: Mid-session dropout/default rate | B8: =Assumptions!$D$16 | C8: =Assumptions!$F$16 | D8: =Engine!$T$94 | E8: =Engine!$U$94 | F8: =ABS(E8-D8) | G8: =Engine!$T$119 | H8: =Engine!$U$119 | I8: =ABS(H8-G8)
A9: Share of students paying full fee upfront | B9: =Assumptions!$D$17 | C9: =Assumptions!$F$17 | D9: =Engine!$V$94 | E9: =Engine!$W$94 | F9: =ABS(E9-D9) | G9: =Engine!$V$119 | H9: =Engine!$W$119 | I9: =ABS(H9-G9)
A10: Instalments per year for non-upfront payers | B10: =Assumptions!$D$18 | C10: =Assumptions!$F$18 | D10: =Engine!$X$94 | E10: =Engine!$Y$94 | F10: =ABS(E10-D10) | G10: =Engine!$X$119 | H10: =Engine!$Y$119 | I10: =ABS(H10-G10)
A11: Dropout reduction among flagged students given outreach (RCT) | B11: =Assumptions!$D$28 | C11: =Assumptions!$F$28 | D11: =Engine!$Z$94 | E11: =Engine!$AA$94 | F11: =ABS(E11-D11) | G11: =Engine!$Z$119 | H11: =Engine!$AA$119 | I11: =ABS(H11-G11)
A12: Model recall on minors (academic-support + rules) | B12: =Assumptions!$D$24 | C12: =Assumptions!$F$24 | D12: =Engine!$AB$94 | E12: =Engine!$AC$94 | F12: =ABS(E12-D12) | G12: =Engine!$AB$119 | H12: =Engine!$AC$119 | I12: =ABS(H12-G12)
A13: Months before the model can flag (no test data yet) | B13: =Assumptions!$D$21 | C13: =Assumptions!$F$21 | D13: =Engine!$AD$94 | E13: =Engine!$AE$94 | F13: =ABS(E13-D13) | G13: =Engine!$AD$119 | H13: =Engine!$AE$119 | I13: =ABS(H13-G13)
A14: Admissions uplift next session from results/parent trust | B14: =Assumptions!$D$29 | C14: =Assumptions!$F$29 | D14: =Engine!$AF$94 | E14: =Engine!$AG$94 | F14: =ABS(E14-D14) | G14: =Engine!$AF$119 | H14: =Engine!$AG$119 | I14: =ABS(H14-G14)
A15: Share of institutes that reclaim our GST as input credit | B15: =Assumptions!$D$36 | C15: =Assumptions!$F$36 | D15: =Engine!$AH$94 | E15: =Engine!$AI$94 | F15: =ABS(E15-D15) | G15: =Engine!$AH$119 | H15: =Engine!$AI$119 | I15: =ABS(H15-G15)
A16: Monthly logo churn for monthly payers | B16: =Assumptions!$D$72 | C16: =Assumptions!$F$72 | D16: =Engine!$AJ$94 | E16: =Engine!$AK$94 | F16: =ABS(E16-D16) | G16: =Engine!$AJ$119 | H16: =Engine!$AK$119 | I16: =ABS(H16-G16)
A17: Non-renewal at session end (annual) | B17: =Assumptions!$D$73 | C17: =Assumptions!$F$73 | D17: =Engine!$AL$94 | E17: =Engine!$AM$94 | F17: =ABS(E17-D17) | G17: =Engine!$AL$119 | H17: =Engine!$AM$119 | I17: =ABS(H17-G17)
A18: Pilot-to-paid conversion | B18: =Assumptions!$D$67 | C18: =Assumptions!$F$67 | D18: =Engine!$AN$94 | E18: =Engine!$AO$94 | F18: =ABS(E18-D18) | G18: =Engine!$AN$119 | H18: =Engine!$AO$119 | I18: =ABS(H18-G18)
A19: Pilots started per rep per month (yearly avg) | B19: =Assumptions!$D$66 | C19: =Assumptions!$F$66 | D19: =Engine!$AP$94 | E19: =Engine!$AQ$94 | F19: =ABS(E19-D19) | G19: =Engine!$AP$119 | H19: =Engine!$AQ$119 | I19: =ABS(H19-G19)
A22: Grid 1 — Institute ROI (Mid, live scenario): list price × effective dropout reduction
A23: Rows: effective reduction · Columns: list price ₹/student/month (blue = grid points)
B24: 20 | C24: 30 | D24: 40 | E24: 50 | F24: 60 | G24: 80
A25: 0.05 | B25: =(Institute_ROI!$E$31*Institute_ROI!$E$39*$A25+Institute_ROI!$E$42+Institute_ROI!$E$43)/(SUMPRODUCT((Institute_ROI!$E$6*Season_Idx*B$24>Institute_ROI!$E$26)*(Institute_ROI!$E$6*Season_Idx*B$24)+(Institute_ROI!$E$6*Season_Idx*B$24<=Institute_ROI!$E$26)*Institute_ROI!$E$26)*(1-Institute_ROI!$E$29)*(1+GST*(1-ITCShare))+Institute_ROI!$E$49) | C25: =(Institute_ROI!$E$31*Institute_ROI!$E$39*$A25+Institute_ROI!$E$42+Institute_ROI!$E$43)/(SUMPRODUCT((Institute_ROI!$E$6*Season_Idx*C$24>Institute_ROI!$E$26)*(Institute_ROI!$E$6*Season_Idx*C$24)+(Institute_ROI!$E$6*Season_Idx*C$24<=Institute_ROI!$E$26)*Institute_ROI!$E$26)*(1-Institute_ROI!$E$29)*(1+GST*(1-ITCShare))+Institute_ROI!$E$49) | D25: =(Institute_ROI!$E$31*Institute_ROI!$E$39*$A25+Institute_ROI!$E$42+Institute_ROI!$E$43)/(SUMPRODUCT((Institute_ROI!$E$6*Season_Idx*D$24>Institute_ROI!$E$26)*(Institute_ROI!$E$6*Season_Idx*D$24)+(Institute_ROI!$E$6*Season_Idx*D$24<=Institute_ROI!$E$26)*Institute_ROI!$E$26)*(1-Institute_ROI!$E$29)*(1+GST*(1-ITCShare))+Institute_ROI!$E$49) | E25: =(Institute_ROI!$E$31*Institute_ROI!$E$39*$A25+Institute_ROI!$E$42+Institute_ROI!$E$43)/(SUMPRODUCT((Institute_ROI!$E$6*Season_Idx*E$24>Institute_ROI!$E$26)*(Institute_ROI!$E$6*Season_Idx*E$24)+(Institute_ROI!$E$6*Season_Idx*E$24<=Institute_ROI!$E$26)*Institute_ROI!$E$26)*(1-Institute_ROI!$E$29)*(1+GST*(1-ITCShare))+Institute_ROI!$E$49) | F25: =(Institute_ROI!$E$31*Institute_ROI!$E$39*$A25+Institute_ROI!$E$42+Institute_ROI!$E$43)/(SUMPRODUCT((Institute_ROI!$E$6*Season_Idx*F$24>Institute_ROI!$E$26)*(Institute_ROI!$E$6*Season_Idx*F$24)+(Institute_ROI!$E$6*Season_Idx*F$24<=Institute_ROI!$E$26)*Institute_ROI!$E$26)*(1-Institute_ROI!$E$29)*(1+GST*(1-ITCShare))+Institute_ROI!$E$49) | G25: =(Institute_ROI!$E$31*Institute_ROI!$E$39*$A25+Institute_ROI!$E$42+Institute_ROI!$E$43)/(SUMPRODUCT((Institute_ROI!$E$6*Season_Idx*G$24>Institute_ROI!$E$26)*(Institute_ROI!$E$6*Season_Idx*G$24)+(Institute_ROI!$E$6*Season_Idx*G$24<=Institute_ROI!$E$26)*Institute_ROI!$E$26)*(1-Institute_ROI!$E$29)*(1+GST*(1-ITCShare))+Institute_ROI!$E$49)
A26: 0.08 | B26: =(Institute_ROI!$E$31*Institute_ROI!$E$39*$A26+Institute_ROI!$E$42+Institute_ROI!$E$43)/(SUMPRODUCT((Institute_ROI!$E$6*Season_Idx*B$24>Institute_ROI!$E$26)*(Institute_ROI!$E$6*Season_Idx*B$24)+(Institute_ROI!$E$6*Season_Idx*B$24<=Institute_ROI!$E$26)*Institute_ROI!$E$26)*(1-Institute_ROI!$E$29)*(1+GST*(1-ITCShare))+Institute_ROI!$E$49) | C26: =(Institute_ROI!$E$31*Institute_ROI!$E$39*$A26+Institute_ROI!$E$42+Institute_ROI!$E$43)/(SUMPRODUCT((Institute_ROI!$E$6*Season_Idx*C$24>Institute_ROI!$E$26)*(Institute_ROI!$E$6*Season_Idx*C$24)+(Institute_ROI!$E$6*Season_Idx*C$24<=Institute_ROI!$E$26)*Institute_ROI!$E$26)*(1-Institute_ROI!$E$29)*(1+GST*(1-ITCShare))+Institute_ROI!$E$49) | D26: =(Institute_ROI!$E$31*Institute_ROI!$E$39*$A26+Institute_ROI!$E$42+Institute_ROI!$E$43)/(SUMPRODUCT((Institute_ROI!$E$6*Season_Idx*D$24>Institute_ROI!$E$26)*(Institute_ROI!$E$6*Season_Idx*D$24)+(Institute_ROI!$E$6*Season_Idx*D$24<=Institute_ROI!$E$26)*Institute_ROI!$E$26)*(1-Institute_ROI!$E$29)*(1+GST*(1-ITCShare))+Institute_ROI!$E$49) | E26: =(Institute_ROI!$E$31*Institute_ROI!$E$39*$A26+Institute_ROI!$E$42+Institute_ROI!$E$43)/(SUMPRODUCT((Institute_ROI!$E$6*Season_Idx*E$24>Institute_ROI!$E$26)*(Institute_ROI!$E$6*Season_Idx*E$24)+(Institute_ROI!$E$6*Season_Idx*E$24<=Institute_ROI!$E$26)*Institute_ROI!$E$26)*(1-Institute_ROI!$E$29)*(1+GST*(1-ITCShare))+Institute_ROI!$E$49) | F26: =(Institute_ROI!$E$31*Institute_ROI!$E$39*$A26+Institute_ROI!$E$42+Institute_ROI!$E$43)/(SUMPRODUCT((Institute_ROI!$E$6*Season_Idx*F$24>Institute_ROI!$E$26)*(Institute_ROI!$E$6*Season_Idx*F$24)+(Institute_ROI!$E$6*Season_Idx*F$24<=Institute_ROI!$E$26)*Institute_ROI!$E$26)*(1-Institute_ROI!$E$29)*(1+GST*(1-ITCShare))+Institute_ROI!$E$49) | G26: =(Institute_ROI!$E$31*Institute_ROI!$E$39*$A26+Institute_ROI!$E$42+Institute_ROI!$E$43)/(SUMPRODUCT((Institute_ROI!$E$6*Season_Idx*G$24>Institute_ROI!$E$26)*(Institute_ROI!$E$6*Season_Idx*G$24)+(Institute_ROI!$E$6*Season_Idx*G$24<=Institute_ROI!$E$26)*Institute_ROI!$E$26)*(1-Institute_ROI!$E$29)*(1+GST*(1-ITCShare))+Institute_ROI!$E$49)
A27: 0.11 | B27: =(Institute_ROI!$E$31*Institute_ROI!$E$39*$A27+Institute_ROI!$E$42+Institute_ROI!$E$43)/(SUMPRODUCT((Institute_ROI!$E$6*Season_Idx*B$24>Institute_ROI!$E$26)*(Institute_ROI!$E$6*Season_Idx*B$24)+(Institute_ROI!$E$6*Season_Idx*B$24<=Institute_ROI!$E$26)*Institute_ROI!$E$26)*(1-Institute_ROI!$E$29)*(1+GST*(1-ITCShare))+Institute_ROI!$E$49) | C27: =(Institute_ROI!$E$31*Institute_ROI!$E$39*$A27+Institute_ROI!$E$42+Institute_ROI!$E$43)/(SUMPRODUCT((Institute_ROI!$E$6*Season_Idx*C$24>Institute_ROI!$E$26)*(Institute_ROI!$E$6*Season_Idx*C$24)+(Institute_ROI!$E$6*Season_Idx*C$24<=Institute_ROI!$E$26)*Institute_ROI!$E$26)*(1-Institute_ROI!$E$29)*(1+GST*(1-ITCShare))+Institute_ROI!$E$49) | D27: =(Institute_ROI!$E$31*Institute_ROI!$E$39*$A27+Institute_ROI!$E$42+Institute_ROI!$E$43)/(SUMPRODUCT((Institute_ROI!$E$6*Season_Idx*D$24>Institute_ROI!$E$26)*(Institute_ROI!$E$6*Season_Idx*D$24)+(Institute_ROI!$E$6*Season_Idx*D$24<=Institute_ROI!$E$26)*Institute_ROI!$E$26)*(1-Institute_ROI!$E$29)*(1+GST*(1-ITCShare))+Institute_ROI!$E$49) | E27: =(Institute_ROI!$E$31*Institute_ROI!$E$39*$A27+Institute_ROI!$E$42+Institute_ROI!$E$43)/(SUMPRODUCT((Institute_ROI!$E$6*Season_Idx*E$24>Institute_ROI!$E$26)*(Institute_ROI!$E$6*Season_Idx*E$24)+(Institute_ROI!$E$6*Season_Idx*E$24<=Institute_ROI!$E$26)*Institute_ROI!$E$26)*(1-Institute_ROI!$E$29)*(1+GST*(1-ITCShare))+Institute_ROI!$E$49) | F27: =(Institute_ROI!$E$31*Institute_ROI!$E$39*$A27+Institute_ROI!$E$42+Institute_ROI!$E$43)/(SUMPRODUCT((Institute_ROI!$E$6*Season_Idx*F$24>Institute_ROI!$E$26)*(Institute_ROI!$E$6*Season_Idx*F$24)+(Institute_ROI!$E$6*Season_Idx*F$24<=Institute_ROI!$E$26)*Institute_ROI!$E$26)*(1-Institute_ROI!$E$29)*(1+GST*(1-ITCShare))+Institute_ROI!$E$49) | G27: =(Institute_ROI!$E$31*Institute_ROI!$E$39*$A27+Institute_ROI!$E$42+Institute_ROI!$E$43)/(SUMPRODUCT((Institute_ROI!$E$6*Season_Idx*G$24>Institute_ROI!$E$26)*(Institute_ROI!$E$6*Season_Idx*G$24)+(Institute_ROI!$E$6*Season_Idx*G$24<=Institute_ROI!$E$26)*Institute_ROI!$E$26)*(1-Institute_ROI!$E$29)*(1+GST*(1-ITCShare))+Institute_ROI!$E$49)
A28: 0.15 | B28: =(Institute_ROI!$E$31*Institute_ROI!$E$39*$A28+Institute_ROI!$E$42+Institute_ROI!$E$43)/(SUMPRODUCT((Institute_ROI!$E$6*Season_Idx*B$24>Institute_ROI!$E$26)*(Institute_ROI!$E$6*Season_Idx*B$24)+(Institute_ROI!$E$6*Season_Idx*B$24<=Institute_ROI!$E$26)*Institute_ROI!$E$26)*(1-Institute_ROI!$E$29)*(1+GST*(1-ITCShare))+Institute_ROI!$E$49) | C28: =(Institute_ROI!$E$31*Institute_ROI!$E$39*$A28+Institute_ROI!$E$42+Institute_ROI!$E$43)/(SUMPRODUCT((Institute_ROI!$E$6*Season_Idx*C$24>Institute_ROI!$E$26)*(Institute_ROI!$E$6*Season_Idx*C$24)+(Institute_ROI!$E$6*Season_Idx*C$24<=Institute_ROI!$E$26)*Institute_ROI!$E$26)*(1-Institute_ROI!$E$29)*(1+GST*(1-ITCShare))+Institute_ROI!$E$49) | D28: =(Institute_ROI!$E$31*Institute_ROI!$E$39*$A28+Institute_ROI!$E$42+Institute_ROI!$E$43)/(SUMPRODUCT((Institute_ROI!$E$6*Season_Idx*D$24>Institute_ROI!$E$26)*(Institute_ROI!$E$6*Season_Idx*D$24)+(Institute_ROI!$E$6*Season_Idx*D$24<=Institute_ROI!$E$26)*Institute_ROI!$E$26)*(1-Institute_ROI!$E$29)*(1+GST*(1-ITCShare))+Institute_ROI!$E$49) | E28: =(Institute_ROI!$E$31*Institute_ROI!$E$39*$A28+Institute_ROI!$E$42+Institute_ROI!$E$43)/(SUMPRODUCT((Institute_ROI!$E$6*Season_Idx*E$24>Institute_ROI!$E$26)*(Institute_ROI!$E$6*Season_Idx*E$24)+(Institute_ROI!$E$6*Season_Idx*E$24<=Institute_ROI!$E$26)*Institute_ROI!$E$26)*(1-Institute_ROI!$E$29)*(1+GST*(1-ITCShare))+Institute_ROI!$E$49) | F28: =(Institute_ROI!$E$31*Institute_ROI!$E$39*$A28+Institute_ROI!$E$42+Institute_ROI!$E$43)/(SUMPRODUCT((Institute_ROI!$E$6*Season_Idx*F$24>Institute_ROI!$E$26)*(Institute_ROI!$E$6*Season_Idx*F$24)+(Institute_ROI!$E$6*Season_Idx*F$24<=Institute_ROI!$E$26)*Institute_ROI!$E$26)*(1-Institute_ROI!$E$29)*(1+GST*(1-ITCShare))+Institute_ROI!$E$49) | G28: =(Institute_ROI!$E$31*Institute_ROI!$E$39*$A28+Institute_ROI!$E$42+Institute_ROI!$E$43)/(SUMPRODUCT((Institute_ROI!$E$6*Season_Idx*G$24>Institute_ROI!$E$26)*(Institute_ROI!$E$6*Season_Idx*G$24)+(Institute_ROI!$E$6*Season_Idx*G$24<=Institute_ROI!$E$26)*Institute_ROI!$E$26)*(1-Institute_ROI!$E$29)*(1+GST*(1-ITCShare))+Institute_ROI!$E$49)
A29: 0.2 | B29: =(Institute_ROI!$E$31*Institute_ROI!$E$39*$A29+Institute_ROI!$E$42+Institute_ROI!$E$43)/(SUMPRODUCT((Institute_ROI!$E$6*Season_Idx*B$24>Institute_ROI!$E$26)*(Institute_ROI!$E$6*Season_Idx*B$24)+(Institute_ROI!$E$6*Season_Idx*B$24<=Institute_ROI!$E$26)*Institute_ROI!$E$26)*(1-Institute_ROI!$E$29)*(1+GST*(1-ITCShare))+Institute_ROI!$E$49) | C29: =(Institute_ROI!$E$31*Institute_ROI!$E$39*$A29+Institute_ROI!$E$42+Institute_ROI!$E$43)/(SUMPRODUCT((Institute_ROI!$E$6*Season_Idx*C$24>Institute_ROI!$E$26)*(Institute_ROI!$E$6*Season_Idx*C$24)+(Institute_ROI!$E$6*Season_Idx*C$24<=Institute_ROI!$E$26)*Institute_ROI!$E$26)*(1-Institute_ROI!$E$29)*(1+GST*(1-ITCShare))+Institute_ROI!$E$49) | D29: =(Institute_ROI!$E$31*Institute_ROI!$E$39*$A29+Institute_ROI!$E$42+Institute_ROI!$E$43)/(SUMPRODUCT((Institute_ROI!$E$6*Season_Idx*D$24>Institute_ROI!$E$26)*(Institute_ROI!$E$6*Season_Idx*D$24)+(Institute_ROI!$E$6*Season_Idx*D$24<=Institute_ROI!$E$26)*Institute_ROI!$E$26)*(1-Institute_ROI!$E$29)*(1+GST*(1-ITCShare))+Institute_ROI!$E$49) | E29: =(Institute_ROI!$E$31*Institute_ROI!$E$39*$A29+Institute_ROI!$E$42+Institute_ROI!$E$43)/(SUMPRODUCT((Institute_ROI!$E$6*Season_Idx*E$24>Institute_ROI!$E$26)*(Institute_ROI!$E$6*Season_Idx*E$24)+(Institute_ROI!$E$6*Season_Idx*E$24<=Institute_ROI!$E$26)*Institute_ROI!$E$26)*(1-Institute_ROI!$E$29)*(1+GST*(1-ITCShare))+Institute_ROI!$E$49) | F29: =(Institute_ROI!$E$31*Institute_ROI!$E$39*$A29+Institute_ROI!$E$42+Institute_ROI!$E$43)/(SUMPRODUCT((Institute_ROI!$E$6*Season_Idx*F$24>Institute_ROI!$E$26)*(Institute_ROI!$E$6*Season_Idx*F$24)+(Institute_ROI!$E$6*Season_Idx*F$24<=Institute_ROI!$E$26)*Institute_ROI!$E$26)*(1-Institute_ROI!$E$29)*(1+GST*(1-ITCShare))+Institute_ROI!$E$49) | G29: =(Institute_ROI!$E$31*Institute_ROI!$E$39*$A29+Institute_ROI!$E$42+Institute_ROI!$E$43)/(SUMPRODUCT((Institute_ROI!$E$6*Season_Idx*G$24>Institute_ROI!$E$26)*(Institute_ROI!$E$6*Season_Idx*G$24)+(Institute_ROI!$E$6*Season_Idx*G$24<=Institute_ROI!$E$26)*Institute_ROI!$E$26)*(1-Institute_ROI!$E$29)*(1+GST*(1-ITCShare))+Institute_ROI!$E$49)
A30: 0.25 | B30: =(Institute_ROI!$E$31*Institute_ROI!$E$39*$A30+Institute_ROI!$E$42+Institute_ROI!$E$43)/(SUMPRODUCT((Institute_ROI!$E$6*Season_Idx*B$24>Institute_ROI!$E$26)*(Institute_ROI!$E$6*Season_Idx*B$24)+(Institute_ROI!$E$6*Season_Idx*B$24<=Institute_ROI!$E$26)*Institute_ROI!$E$26)*(1-Institute_ROI!$E$29)*(1+GST*(1-ITCShare))+Institute_ROI!$E$49) | C30: =(Institute_ROI!$E$31*Institute_ROI!$E$39*$A30+Institute_ROI!$E$42+Institute_ROI!$E$43)/(SUMPRODUCT((Institute_ROI!$E$6*Season_Idx*C$24>Institute_ROI!$E$26)*(Institute_ROI!$E$6*Season_Idx*C$24)+(Institute_ROI!$E$6*Season_Idx*C$24<=Institute_ROI!$E$26)*Institute_ROI!$E$26)*(1-Institute_ROI!$E$29)*(1+GST*(1-ITCShare))+Institute_ROI!$E$49) | D30: =(Institute_ROI!$E$31*Institute_ROI!$E$39*$A30+Institute_ROI!$E$42+Institute_ROI!$E$43)/(SUMPRODUCT((Institute_ROI!$E$6*Season_Idx*D$24>Institute_ROI!$E$26)*(Institute_ROI!$E$6*Season_Idx*D$24)+(Institute_ROI!$E$6*Season_Idx*D$24<=Institute_ROI!$E$26)*Institute_ROI!$E$26)*(1-Institute_ROI!$E$29)*(1+GST*(1-ITCShare))+Institute_ROI!$E$49) | E30: =(Institute_ROI!$E$31*Institute_ROI!$E$39*$A30+Institute_ROI!$E$42+Institute_ROI!$E$43)/(SUMPRODUCT((Institute_ROI!$E$6*Season_Idx*E$24>Institute_ROI!$E$26)*(Institute_ROI!$E$6*Season_Idx*E$24)+(Institute_ROI!$E$6*Season_Idx*E$24<=Institute_ROI!$E$26)*Institute_ROI!$E$26)*(1-Institute_ROI!$E$29)*(1+GST*(1-ITCShare))+Institute_ROI!$E$49) | F30: =(Institute_ROI!$E$31*Institute_ROI!$E$39*$A30+Institute_ROI!$E$42+Institute_ROI!$E$43)/(SUMPRODUCT((Institute_ROI!$E$6*Season_Idx*F$24>Institute_ROI!$E$26)*(Institute_ROI!$E$6*Season_Idx*F$24)+(Institute_ROI!$E$6*Season_Idx*F$24<=Institute_ROI!$E$26)*Institute_ROI!$E$26)*(1-Institute_ROI!$E$29)*(1+GST*(1-ITCShare))+Institute_ROI!$E$49) | G30: =(Institute_ROI!$E$31*Institute_ROI!$E$39*$A30+Institute_ROI!$E$42+Institute_ROI!$E$43)/(SUMPRODUCT((Institute_ROI!$E$6*Season_Idx*G$24>Institute_ROI!$E$26)*(Institute_ROI!$E$6*Season_Idx*G$24)+(Institute_ROI!$E$6*Season_Idx*G$24<=Institute_ROI!$E$26)*Institute_ROI!$E$26)*(1-Institute_ROI!$E$29)*(1+GST*(1-ITCShare))+Institute_ROI!$E$49)
A33: Grid 2 — LTV ÷ acquisition cost (Mid, live scenario): monthly churn × acquisition cost
A34: Monthly in-season churn (blue) → LTV from Engine | B34: 0.01 | C34: 0.02 | D34: 0.03 | E34: 0.04 | F34: 0.05
A35: LTV at that churn (₹) | B35: =Engine!$AR$118 | C35: =Engine!$AS$118 | D35: =Engine!$AT$118 | E35: =Engine!$AU$118 | F35: =Engine!$AV$118
A36: Acquisition cost ₹ ↓
A37: 15000 | B37: =B$35/$A37 | C37: =C$35/$A37 | D37: =D$35/$A37 | E37: =E$35/$A37 | F37: =F$35/$A37
A38: 25000 | B38: =B$35/$A38 | C38: =C$35/$A38 | D38: =D$35/$A38 | E38: =E$35/$A38 | F38: =F$35/$A38
A39: 35000 | B39: =B$35/$A39 | C39: =C$35/$A39 | D39: =D$35/$A39 | E39: =E$35/$A39 | F39: =F$35/$A39
A40: 50000 | B40: =B$35/$A40 | C40: =C$35/$A40 | D40: =D$35/$A40 | E40: =E$35/$A40 | F40: =F$35/$A40
A41: 75000 | B41: =B$35/$A41 | C41: =C$35/$A41 | D41: =D$35/$A41 | E41: =E$35/$A41 | F41: =F$35/$A41
A43: Reading: ROI < 1.0x red, 1–2x amber, ≥ 2x green. LTV/CAC < 3x red.

Sheet Checks
A1: Checks — any red flag means the model is not safe to quote
A3: Check | B3: Type | C3: Value | D3: Flag (1 = fail)
A4: Scenario selector is 1, 2 or 3 | B4: Error | C4: =Scenario | D4: =IF(OR(Scenario=1,Scenario=2,Scenario=3),0,1)
A5: Dropout timing curve sums to 100% | B5: Error | C5: =SUM(DropTiming) | D5: =IF(ABS(C5-1)<0.0001,0,1)
A6: Percent inputs within 0–100% | B6: Error | C6: =SUM(Assumptions!L5:L93) | D6: =IF(C6=0,0,1)
A7: Live values within Bear–Bull range | B7: Error | C7: =SUM(Assumptions!M5:M93) | D7: =IF(C7=0,0,1)
A8: At least one renewal month (avoids ÷0) | B8: Error | C8: =NRenew | D8: =IF(C8>=1,0,1)
A9: Active-student index between 0 and 1.2 | B9: Error | C9: =SUMPRODUCT((Season_Idx<0)+(Season_Idx>1.2)) | D9: =IF(C9=0,0,1)
A10: Effective reduction ≤ RCT effect (Mid) | B10: Error | C10: =Institute_ROI!E37-InterventionSuccess | D10: =IF(C10<=0.000001,0,1)
A11: Instalments ≥ 1 and ≤ course months | B11: Error | C11: =NInstalments | D11: =IF(AND(C11>=1,C11<=CourseMonths,C11=INT(C11)),0,1)
A12: Engine reproduces Institute_ROI ROI (S) | B12: Error | C12: =ABS(Institute_ROI!D53-Engine!$D$94) | D12: =IF(C12<0.000001,0,1)
A13: Engine reproduces Unit_Econ LTV (S) | B13: Error | C13: =ABS(Unit_Econ!D48-Engine!$D$118) | D13: =IF(C13<0.000001,0,1)
A14: Engine reproduces Institute_ROI ROI (M) | B14: Error | C14: =ABS(Institute_ROI!E53-Engine!$E$94) | D14: =IF(C14<0.000001,0,1)
A15: Engine reproduces Unit_Econ LTV (M) | B15: Error | C15: =ABS(Unit_Econ!E48-Engine!$E$118) | D15: =IF(C15<0.000001,0,1)
A16: Engine reproduces Institute_ROI ROI (L) | B16: Error | C16: =ABS(Institute_ROI!F53-Engine!$F$94) | D16: =IF(C16<0.000001,0,1)
A17: Engine reproduces Unit_Econ LTV (L) | B17: Error | C17: =ABS(Unit_Econ!F48-Engine!$F$118) | D17: =IF(C17<0.000001,0,1)
A18: Survival curve stays within 0–1 (Mid) | B18: Error | C18: =IF(AND(MIN(Unit_Econ!E172:E231)>=0,MAX(Unit_Econ!E172:E231)<=1),0,1) | D18: =C18
A19: Guide ROI reproduces the brief's 2.25x | B19: Error | C19: =Institute_ROI!$E$68 | D19: =IF(ABS(C19-2.25)<0.01,0,1)
A20: WARNING: RCT effect exceeds share of dropouts that are preventable | B20: Warning | C20: =InterventionSuccess-Preventable | D20: =IF(C20<=0,0,1)
A21: WARNING: list price above the highest ERP/LMS anchor found (₹21/student/month) | B21: Warning | C21: =ListPrice | D21: =IF(C21<=CompetitorAnchorHigh,0,1)
A22: WARNING: months with negative contribution (Mid) | B22: Warning | C22: =COUNTIF(Unit_Econ!E112:E171,"<0") | D22: =IF(C22=0,0,1)
A23: WARNING: all-in COGS outside tech band ₹3–10 per student-month | B23: Warning | C23: =COGS_AllIn | D23: =IF(AND(C23>=3,C23<=10),0,1)
A24: WARNING: Mid institute ROI below 1.0x | B24: Warning | C24: =Institute_ROI!E53 | D24: =IF(C24>=1,0,1)
